Workbook
Name BAIRROS_SAO_SEBASTIAO: Bairros!$A$6:$A$41
Name BAIRROS_BERTIOGA: Bairros!$E$6:$E$24
Name LISTA_CIDADES: Listas!$A$2:$A$3
Name LISTA_TIPOS: Listas!$B$2:$B$8
Name LISTA_PADROES: Listas!$C$2:$C$5
Name LISTA_ORIGEM_PADRAO: Listas!$D$2:$D$5
Name LISTA_NATUREZAS: Listas!$E$2:$E$2
Name LISTA_FONTES: Listas!$F$2:$F$3
Name LISTA_ORIGEM_FOTO: Listas!$G$2:$G$5
Name LISTA_FORMA_PAGAMENTO: Listas!$H$2:$H$4
Name LISTA_STATUS: Listas!$I$2:$I$4
Name AMOSTRA_MIN: 'Análise ITBI'!$B$4

Sheet Instruções
A1: Base de imóveis vendidos — São Sebastião e Bertioga
A3: Tópico | B3: Descrição
A4: O que é | B4: Base de vendas efetivas de imóveis com o valor REAL de venda (escritura/registro ou ITBI), nunca o valor anunciado. Cada linha precisa de um documento comprobatório.
A5: Por que começa vazia | B5: Não existem dados públicos de vendas para estas cidades. Os dados entram à medida que chegam as respostas dos pedidos LAI e as certidões de matrícula.
A6: Onde digitar | B6: Aba Vendas. Células comuns = entrada. Células cinza = fórmulas (não editar): R$/m², Alerta e Street View. Passe o mouse no cabeçalho para ver a explicação de cada coluna.
A7: Importar LAI | B7: python scripts/importar_lai.py <arquivo_da_prefeitura> <mapa_colunas.json>
A8: Fotos | B8: Salve as fotos em fotos/ com o nome do ID (ex.: fotos/CRI-SS-12345-R7.jpg; várias: ..._2.jpg) e rode python scripts/vincular_fotos.py. A coluna 'Foto da fachada' recebe o link e a aba Galeria mostra as miniaturas.
A9: Resumo | B9: Aba Resumo: por cidade/bairro e por padrão, só com linhas Validado.
A10: Regras | B10: Aba Regras. Critério de padrão na aba Padrão. Documentos recebidos na aba Fontes.
A12: Exemplo de preenchimento (FICTÍCIO — só mostra o formato; não é dado real e não está na aba Vendas)
A13: ID | B13: CRI-SS-00000-R0
A14: Cidade | B14: São Sebastião
A15: Bairro | B15: Maresias
A16: Logradouro e nº | B16: Rua Exemplo, 000
A17: Condomínio / Complemento | B17: Cond. Exemplo, casa 0
A18: Inscrição imobiliária | B18: 0000.000.000
A19: Tipo | B19: Casa em condomínio
A20: Área construída/privativa (m²) | B20: 000,00
A21: Área do terreno (m²) | B21: 000,00
A22: Padrão | B22: Alto
A23: Origem do padrão | B23: Certidão/memorial/habite-se
A24: Padrão (texto do documento) | B24: texto literal
... A49: Status | B49: Validado
A50: Observações

Sheet Vendas
A1: ID | B1: Cidade | C1: Bairro | D1: Logradouro e nº | E1: Condomínio / Complemento | F1: Inscrição imobiliária | G1: Tipo | H1: Área construída/privativa (m²) | I1: Área do terreno (m²) | J1: Padrão | K1: Origem do padrão | L1: Padrão (texto do documento) | M1: Valor de venda (R$) | N1: Base de cálculo ITBI (R$) | O1: Valor venal IPTU (R$) | P1: Forma de pagamento | Q1: Valor financiado (R$) | R1: Valor p/ leilão – alienação fiduciária (R$) | S1: R$/m² (calculado) | T1: Alerta | U1: Declarado ÷ Base ITBI | V1: Declarado ÷ Venal IPTU | W1: Declarado ÷ Valor leilão | X1: Financiado ÷ Declarado | Y1: Ano | Z1: Data da escritura / transação | AA1: Data do registro | AB1: Natureza | AC1: Fonte | AD1: Documento comprobatório | AE1: CRI / Órgão | AF1: Coordenadas (lat,long) | AG1: Foto da fachada | AH1: Origem da foto | AI1: Data da foto | AJ1: Street View | AK1: Status | AL1: Observações
S2: =IF(NOT(ISNUMBER(M2)),"",IF(G2="Terreno",IF(AND(ISNUMBER(I2),I2>0),M2/I2,""),IF(AND(ISNUMBER(H2),H2>0),M2/H2,""))) | T2: =IF(AND(ISNUMBER(M2),ISNUMBER(O2)),IF(M2<=O2,"Valor ≤ venal IPTU",""),"") | U2: =IF(AND(ISNUMBER(M2),ISNUMBER(N2)),IF(N2>0,M2/N2,""),"") | V2: =IF(AND(ISNUMBER(M2),ISNUMBER(O2)),IF(O2>0,M2/O2,""),"") | W2: =IF(AND(ISNUMBER(M2),ISNUMBER(R2)),IF(R2>0,M2/R2,""),"") | X2: =IF(AND(ISNUMBER(Q2),ISNUMBER(M2)),IF(M2>0,Q2/M2,""),"") | Y2: =IF(ISNUMBER(Z2),YEAR(Z2),"") | AJ2: =IF(LEN(TRIM(AF2))=0,"",HYPERLINK("https://www.google.com/maps/@?api=1&map_action=pano&viewpoint="&SUBSTITUTE(AF2," ",""),"Abrir Street View"))
S3: =IF(NOT(ISNUMBER(M3)),"",IF(G3="Terreno",IF(AND(ISNUMBER(I3),I3>0),M3/I3,""),IF(AND(ISNUMBER(H3),H3>0),M3/H3,""))) | T3: =IF(AND(ISNUMBER(M3),ISNUMBER(O3)),IF(M3<=O3,"Valor ≤ venal IPTU",""),"") | U3: =IF(AND(ISNUMBER(M3),ISNUMBER(N3)),IF(N3>0,M3/N3,""),"") | V3: =IF(AND(ISNUMBER(M3),ISNUMBER(O3)),IF(O3>0,M3/O3,""),"") | W3: =IF(AND(ISNUMBER(M3),ISNUMBER(R3)),IF(R3>0,M3/R3,""),"") | X3: =IF(AND(ISNUMBER(Q3),ISNUMBER(M3)),IF(M3>0,Q3/M3,""),"") | Y3: =IF(ISNUMBER(Z3),YEAR(Z3),"") | AJ3: =IF(LEN(TRIM(AF3))=0,"",HYPERLINK("https://www.google.com/maps/@?api=1&map_action=pano&viewpoint="&SUBSTITUTE(AF3," ",""),"Abrir Street View"))
S4: =IF(NOT(ISNUMBER(M4)),"",IF(G4="Terreno",IF(AND(ISNUMBER(I4),I4>0),M4/I4,""),IF(AND(ISNUMBER(H4),H4>0),M4/H4,""))) | T4: =IF(AND(ISNUMBER(M4),ISNUMBER(O4)),IF(M4<=O4,"Valor ≤ venal IPTU",""),"") | U4: =IF(AND(ISNUMBER(M4),ISNUMBER(N4)),IF(N4>0,M4/N4,""),"") | V4: =IF(AND(ISNUMBER(M4),ISNUMBER(O4)),IF(O4>0,M4/O4,""),"") | W4: =IF(AND(ISNUMBER(M4),ISNUMBER(R4)),IF(R4>0,M4/R4,""),"") | X4: =IF(AND(ISNUMBER(Q4),ISNUMBER(M4)),IF(M4>0,Q4/M4,""),"") | Y4: =IF(ISNUMBER(Z4),YEAR(Z4),"") | AJ4: =IF(LEN(TRIM(AF4))=0,"",HYPERLINK("https://www.google.com/maps/@?api=1&map_action=pano&viewpoint="&SUBSTITUTE(AF4," ",""),"Abrir Street View"))
S5: =IF(NOT(ISNUMBER(M5)),"",IF(G5="Terreno",IF(AND(ISNUMBER(I5),I5>0),M5/I5,""),IF(AND(ISNUMBER(H5),H5>0),M5/H5,""))) | T5: =IF(AND(ISNUMBER(M5),ISNUMBER(O5)),IF(M5<=O5,"Valor ≤ venal IPTU",""),"") | U5: =IF(AND(ISNUMBER(M5),ISNUMBER(N5)),IF(N5>0,M5/N5,""),"") | V5: =IF(AND(ISNUMBER(M5),ISNUMBER(O5)),IF(O5>0,M5/O5,""),"") | W5: =IF(AND(ISNUMBER(M5),ISNUMBER(R5)),IF(R5>0,M5/R5,""),"") | X5: =IF(AND(ISNUMBER(Q5),ISNUMBER(M5)),IF(M5>0,Q5/M5,""),"") | Y5: =IF(ISNUMBER(Z5),YEAR(Z5),"") | AJ5: =IF(LEN(TRIM(AF5))=0,"",HYPERLINK("https://www.google.com/maps/@?api=1&map_action=pano&viewpoint="&SUBSTITUTE(AF5," ",""),"Abrir Street View"))
S6: =IF(NOT(ISNUMBER(M6)),"",IF(G6="Terreno",IF(AND(ISNUMBER(I6),I6>0),M6/I6,""),IF(AND(ISNUMBER(H6),H6>0),M6/H6,""))) | T6: =IF(AND(ISNUMBER(M6),ISNUMBER(O6)),IF(M6<=O6,"Valor ≤ venal IPTU",""),"") | U6: =IF(AND(ISNUMBER(M6),ISNUMBER(N6)),IF(N6>0,M6/N6,""),"") | V6: =IF(AND(ISNUMBER(M6),ISNUMBER(O6)),IF(O6>0,M6/O6,""),"") | W6: =IF(AND(ISNUMBER(M6),ISNUMBER(R6)),IF(R6>0,M6/R6,""),"") | X6: =IF(AND(ISNUMBER(Q6),ISNUMBER(M6)),IF(M6>0,Q6/M6,""),"") | Y6: =IF(ISNUMBER(Z6),YEAR(Z6),"") | AJ6: =IF(LEN(TRIM(AF6))=0,"",HYPERLINK("https://www.google.com/maps/@?api=1&map_action=pano&viewpoint="&SUBSTITUTE(AF6," ",""),"Abrir Street View"))
S7: =IF(NOT(ISNUMBER(M7)),"",IF(G7="Terreno",IF(AND(ISNUMBER(I7),I7>0),M7/I7,""),IF(AND(ISNUMBER(H7),H7>0),M7/H7,""))) | T7: =IF(AND(ISNUMBER(M7),ISNUMBER(O7)),IF(M7<=O7,"Valor ≤ venal IPTU",""),"") | U7: =IF(AND(ISNUMBER(M7),ISNUMBER(N7)),IF(N7>0,M7/N7,""),"") | V7: =IF(AND(ISNUMBER(M7),ISNUMBER(O7)),IF(O7>0,M7/O7,""),"") | W7: =IF(AND(ISNUMBER(M7),ISNUMBER(R7)),IF(R7>0,M7/R7,""),"") | X7: =IF(AND(ISNUMBER(Q7),ISNUMBER(M7)),IF(M7>0,Q7/M7,""),"") | Y7: =IF(ISNUMBER(Z7),YEAR(Z7),"") | AJ7: =IF(LEN(TRIM(AF7))=0,"",HYPERLINK("https://www.google.com/maps/@?api=1&map_action=pano&viewpoint="&SUBSTITUTE(AF7," ",""),"Abrir Street View"))
S8: =IF(NOT(ISNUMBER(M8)),"",IF(G8="Terreno",IF(AND(ISNUMBER(I8),I8>0),M8/I8,""),IF(AND(ISNUMBER(H8),H8>0),M8/H8,""))) | T8: =IF(AND(ISNUMBER(M8),ISNUMBER(O8)),IF(M8<=O8,"Valor ≤ venal IPTU",""),"") | U8: =IF(AND(ISNUMBER(M8),ISNUMBER(N8)),IF(N8>0,M8/N8,""),"") | V8: =IF(AND(ISNUMBER(M8),ISNUMBER(O8)),IF(O8>0,M8/O8,""),"") | W8: =IF(AND(ISNUMBER(M8),ISNUMBER(R8)),IF(R8>0,M8/R8,""),"") | X8: =IF(AND(ISNUMBER(Q8),ISNUMBER(M8)),IF(M8>0,Q8/M8,""),"") | Y8: =IF(ISNUMBER(Z8),YEAR(Z8),"") | AJ8: =IF(LEN(TRIM(AF8))=0,"",HYPERLINK("https://www.google.com/maps/@?api=1&map_action=pano&viewpoint="&SUBSTITUTE(AF8," ",""),"Abrir Street View"))
S9: =IF(NOT(ISNUMBER(M9)),"",IF(G9="Terreno",IF(AND(ISNUMBER(I9),I9>0),M9/I9,""),IF(AND(ISNUMBER(H9),H9>0),M9/H9,""))) | T9: =IF(AND(ISNUMBER(M9),ISNUMBER(O9)),IF(M9<=O9,"Valor ≤ venal IPTU",""),"") | U9: =IF(AND(ISNUMBER(M9),ISNUMBER(N9)),IF(N9>0,M9/N9,""),"") | V9: =IF(AND(ISNUMBER(M9),ISNUMBER(O9)),IF(O9>0,M9/O9,""),"") | W9: =IF(AND(ISNUMBER(M9),ISNUMBER(R9)),IF(R9>0,M9/R9,""),"") | X9: =IF(AND(ISNUMBER(Q9),ISNUMBER(M9)),IF(M9>0,Q9/M9,""),"") | Y9: =IF(ISNUMBER(Z9),YEAR(Z9),"") | AJ9: =IF(LEN(TRIM(AF9))=0,"",HYPERLINK("https://www.google.com/maps/@?api=1&map_action=pano&viewpoint="&SUBSTITUTE(AF9," ",""),"Abrir Street View"))
S10: =IF(NOT(ISNUMBER(M10)),"",IF(G10="Terreno",IF(AND(ISNUMBER(I10),I10>0),M10/I10,""),IF(AND(ISNUMBER(H10),H10>0),M10/H10,""))) | T10: =IF(AND(ISNUMBER(M10),ISNUMBER(O10)),IF(M10<=O10,"Valor ≤ venal IPTU",""),"") | U10: =IF(AND(ISNUMBER(M10),ISNUMBER(N10)),IF(N10>0,M10/N10,""),"") | V10: =IF(AND(ISNUMBER(M10),ISNUMBER(O10)),IF(O10>0,M10/O10,""),"") | W10: =IF(AND(ISNUMBER(M10),ISNUMBER(R10)),IF(R10>0,M10/R10,""),"") | X10: =IF(AND(ISNUMBER(Q10),ISNUMBER(M10)),IF(M10>0,Q10/M10,""),"") | Y10: =IF(ISNUMBER(Z10),YEAR(Z10),"") | AJ10: =IF(LEN(TRIM(AF10))=0,"",HYPERLINK("https://www.google.com/maps/@?api=1&map_action=pano&viewpoint="&SUBSTITUTE(AF10," ",""),"Abrir Street View"))
S11: =IF(NOT(ISNUMBER(M11)),"",IF(G11="Terreno",IF(AND(ISNUMBER(I11),I11>0),M11/I11,""),IF(AND(ISNUMBER(H11),H11>0),M11/H11,""))) | T11: =IF(AND(ISNUMBER(M11),ISNUMBER(O11)),IF(M11<=O11,"Valor ≤ venal IPTU",""),"") | U11: =IF(AND(ISNUMBER(M11),ISNUMBER(N11)),IF(N11>0,M11/N11,""),"") | V11: =IF(AND(ISNUMBER(M11),ISNUMBER(O11)),IF(O11>0,M11/O11,""),"") | W11: =IF(AND(ISNUMBER(M11),ISNUMBER(R11)),IF(R11>0,M11/R11,""),"") | X11: =IF(AND(ISNUMBER(Q11),ISNUMBER(M11)),IF(M11>0,Q11/M11,""),"") | Y11: =IF(ISNUMBER(Z11),YEAR(Z11),"") | AJ11: =IF(LEN(TRIM(AF11))=0,"",HYPERLINK("https://www.google.com/maps/@?api=1&map_action=pano&viewpoint="&SUBSTITUTE(AF11," ",""),"Abrir Street View"))
S12: =IF(NOT(ISNUMBER(M12)),"",IF(G12="Terreno",IF(AND(ISNUMBER(I12),I12>0),M12/I12,""),IF(AND(ISNUMBER(H12),H12>0),M12/H12,""))) | T12: =IF(AND(ISNUMBER(M12),ISNUMBER(O12)),IF(M12<=O12,"Valor ≤ venal IPTU",""),"") | U12: =IF(AND(ISNUMBER(M12),ISNUMBER(N12)),IF(N12>0,M12/N12,""),"") | V12: =IF(AND(ISNUMBER(M12),ISNUMBER(O12)),IF(O12>0,M12/O12,""),"") | W12: =IF(AND(ISNUMBER(M12),ISNUMBER(R12)),IF(R12>0,M12/R12,""),"") | X12: =IF(AND(ISNUMBER(Q12),ISNUMBER(M12)),IF(M12>0,Q12/M12,""),"") | Y12: =IF(ISNUMBER(Z12),YEAR(Z12),"") | AJ12: =IF(LEN(TRIM(AF12))=0,"",HYPERLINK("https://www.google.com/maps/@?api=1&map_action=pano&viewpoint="&SUBSTITUTE(AF12," ",""),"Abrir Street View"))
S13: =IF(NOT(ISNUMBER(M13)),"",IF(G13="Terreno",IF(AND(ISNUMBER(I13),I13>0),M13/I13,""),IF(AND(ISNUMBER(H13),H13>0),M13/H13,""))) | T13: =IF(AND(ISNUMBER(M13),ISNUMBER(O13)),IF(M13<=O13,"Valor ≤ venal IPTU",""),"") | U13: =IF(AND(ISNUMBER(M13),ISNUMBER(N13)),IF(N13>0,M13/N13,""),"") | V13: =IF(AND(ISNUMBER(M13),ISNUMBER(O13)),IF(O13>0,M13/O13,""),"") | W13: =IF(AND(ISNUMBER(M13),ISNUMBER(R13)),IF(R13>0,M13/R13,""),"") | X13: =IF(AND(ISNUMBER(Q13),ISNUMBER(M13)),IF(M13>0,Q13/M13,""),"") | Y13: =IF(ISNUMBER(Z13),YEAR(Z13),"") | AJ13: =IF(LEN(TRIM(AF13))=0,"",HYPERLINK("https://www.google.com/maps/@?api=1&map_action=pano&viewpoint="&SUBSTITUTE(AF13," ",""),"Abrir Street View"))
... S3001: =IF(NOT(ISNUMBER(M3001)),"",IF(G3001="Terreno",IF(AND(ISNUMBER(I3001),I3001>0),M3001/I3001,""),IF(AND(ISNUMBER(H3001),H3001>0),M3001/H3001,""))) | T3001: =IF(AND(ISNUMBER(M3001),ISNUMBER(O3001)),IF(M3001<=O3001,"Valor ≤ venal IPTU",""),"") | U3001: =IF(AND(ISNUMBER(M3001),ISNUMBER(N3001)),IF(N3001>0,M3001/N3001,""),"") | V3001: =IF(AND(ISNUMBER(M3001),ISNUMBER(O3001)),IF(O3001>0,M3001/O3001,""),"") | W3001: =IF(AND(ISNUMBER(M3001),ISNUMBER(R3001)),IF(R3001>0,M3001/R3001,""),"") | X3001: =IF(AND(ISNUMBER(Q3001),ISNUMBER(M3001)),IF(M3001>0,Q3001/M3001,""),"") | Y3001: =IF(ISNUMBER(Z3001),YEAR(Z3001),"") | AJ3001: =IF(LEN(TRIM(AF3001))=0,"",HYPERLINK("https://www.google.com/maps/@?api=1&map_action=pano&viewpoint="&SUBSTITUTE(AF3001," ",""),"Abrir Street View"))

Sheet Bairros
A1: Bairros oficiais por cidade
A3: São Sebastião | E3: Bertioga
A4: Fonte: IBGE, Censo 2022, malha de bairros SP_bairros_CD2022 — https://geoftp.ibge.gov.br/organizacao_do_territorio/malhas_territoriais/malhas_de_setores_censitarios__divisoes_intramunicipais/censo_2022/bairros/shp/UF/SP_bairros_CD2022.zip (não foi localizada lei municipal de bairros) | E4: Fonte: Lei Complementar nº 99/2013 de Bertioga, Anexo 1 — https://www.bertioga.sp.gov.br/wp/wp-content/uploads/2015/06/Lei-Complementar-99.2013.pdf
A5: Bairro | B5: Código | C5: Observação | E5: Bairro | F5: Código | G5: Observação
A6: Enseada | B6: 3550704001 | C6: Distrito São Francisco da Praia | E6: Caiubura | F6: 01 | G6: RA1 Sul
A7: Jaraguá | B7: 3550704002 | C7: Distrito São Francisco da Praia | E7: São João | F7: 02 | G7: RA1 Sul
A8: Cigarras | B8: 3550704003 | C8: Distrito São Francisco da Praia | E8: Centro | F8: 03 | G8: RA2 Central
A9: São Francisco | B9: 3550704004 | C9: Distrito São Francisco da Praia | E9: Jardim Vicente de Carvalho | F9: 04 | G9: RA2 Central
A10: Morro do Abrigo | B10: 3550704005 | C10: Distrito São Francisco da Praia | E10: Albatróz | F10: 05 | G10: RA2 Central
A11: Olaria | B11: 3550704006 / 3550704036 | C11: O IBGE registra dois setores 'Olaria' (distritos São Francisco da Praia e São Sebastião) | E11: Maitinga | F11: 06 | G11: RA2 Central
A12: Arrastão | B12: 3550704007 | C12: Distrito São Francisco da Praia | E12: Rio da Praia | F12: 07 | G12: RA2 Central
A13: Pontal da Cruz | B13: 3550704008 | C13: Distrito São Sebastião | E13: Buriqui Costa Nativa (Brasfanta) | F13: 08 | G13: RA2 Central
A14: Praia Deserta | B14: 3550704009 | C14: Distrito São Sebastião | E14: Jardim Raphael | F14: 09 | G14: RA2 Central — conhecido popularmente como São Rafael
A15: Porto Grande | B15: 3550704010 | C15: Distrito São Sebastião | E15: Bairro Chácaras | F15: 10 | G15: RA3 Média
A16: Centro | B16: 3550704011 | C16: Distrito São Sebastião | E16: Vista Linda | F16: 11 | G16: RA3 Média
... A24: Calhetas | B24: 3550704019 | C24: Distrito São Sebastião | E24: T.I. (Terras Indígenas do Rio Silveiras) | F24: 19 | G24: RA4 Norte
A25: Toque-Toque Pequeno | B25: 3550704020 | C25: Distrito São Sebastião
A26: Santiago | B26: 3550704021 | C26: Distrito Maresias
A27: Paúba | B27: 3550704022 | C27: Distrito Maresias
A28: Maresias | B28: 3550704023 | C28: Distrito Maresias
A29: Boiçucanga | B29: 3550704024 | C29: Distrito Maresias
A30: Camburi | B30: 3550704025 | C30: Distrito Maresias
A31: Baleia | B31: 3550704026 | C31: Distrito Maresias
A32: Barra do Sahy | B32: 3550704027 | C32: Distrito Maresias
A33: Juqueí | B33: 3550704028 | C33: Distrito Maresias — grafia IBGE (também escrito Juquehy)
A34: Barra do Una | B34: 3550704029 | C34: Distrito Maresias
A35: Boracéia | B35: 3550704030 | C35: Distrito Maresias
A36: Canto do Mar | B36: 3550704031 | C36: Distrito São Francisco da Praia
... A41: Engenho | B41: 3550704039 | C41: Distrito Maresias

Sheet Listas
A1: Cidades | B1: Tipos | C1: Padrões | D1: Origem do padrão | E1: Natureza | F1: Fontes | G1: Origem da foto | H1: Forma de pagamento | I1: Status
A2: São Sebastião | B2: Casa | C2: Baixo | D2: Cadastro municipal (ITBI/IPTU) | E2: Compra e venda | F2: LAI – ITBI Prefeitura | G2: Foto própria no local | H2: Financiado | I2: Validado
A3: Bertioga | B3: Casa em condomínio | C3: Normal | D3: Certidão/memorial/habite-se | F3: Certidão de matrícula (CRI) | G3: Google Street View (link) | H3: À vista | I3: Pendente de conferência
B4: Apartamento | C4: Alto | D4: Vistoria própria (critério NBR 12721) | G4: Foto da certidão/laudo | H4: Não informado | I4: Rejeitado
B5: Terreno | C5: Não informado | D5: Não informado | G5: Sem foto
B6: Sala/Loja comercial
B7: Galpão
B8: Outro

Sheet Resumo
A1: Resumo por cidade e bairro (somente vendas com Status = Validado)
A2: Fórmulas recalculam sozinhas. Bairros sem venda validada mostram '-'. Mediana e R$/m² ignoram linhas sem metragem.
A4: Cidade | B4: Bairro | C4: Nº de vendas | D4: Valor mediano (R$) | E4: Menor valor (R$) | F4: Maior valor (R$) | G4: R$/m² mediano | H4: Nº c/ alerta venal | I4: Venda mais antiga | J4: Venda mais recente
A5: São Sebastião | B5: Enseada | C5: =COUNTIFS(Vendas!$B$2:$B$3001,$A5,Vendas!$C$2:$C$3001,$B5,Vendas!$AK$2:$AK$3001,"Validado") | D5: {=IF(C5=0,"-",MEDIAN(IF((Vendas!$B$2:$B$3001=$A5)*(Vendas!$C$2:$C$3001=$B5)*(Vendas!$AK$2:$AK$3001="Validado")*ISNUMBER(Vendas!$M$2:$M$3001),Vendas!$M$2:$M$3001)))} | E5: =IF(C5=0,"-",_xlfn.MINIFS(Vendas!$M$2:$M$3001,Vendas!$B$2:$B$3001,$A5,Vendas!$C$2:$C$3001,$B5,Vendas!$AK$2:$AK$3001,"Validado")) | F5: =IF(C5=0,"-",_xlfn.MAXIFS(Vendas!$M$2:$M$3001,Vendas!$B$2:$B$3001,$A5,Vendas!$C$2:$C$3001,$B5,Vendas!$AK$2:$AK$3001,"Validado")) | G5: {=IF(SUMPRODUCT((Vendas!$B$2:$B$3001=$A5)*(Vendas!$C$2:$C$3001=$B5)*(Vendas!$AK$2:$AK$3001="Validado")*ISNUMBER(Vendas!$S$2:$S$3001))=0,"-",MEDIAN(IF((Vendas!$B$2:$B$3001=$A5)*(Vendas!$C$2:$C$3001=$B5)*(Vendas!$AK$2:$AK$3001="Validado")*ISNUMBER(Vendas!$S$2:$S$3001),Vendas!$S$2:$S$3001)))} | H5: =COUNTIFS(Vendas!$B$2:$B$3001,$A5,Vendas!$C$2:$C$3001,$B5,Vendas!$AK$2:$AK$3001,"Validado",Vendas!$T$2:$T$3001,"Valor*") | I5: =IF(C5=0,"-",_xlfn.MINIFS(Vendas!$Z$2:$Z$3001,Vendas!$B$2:$B$3001,$A5,Vendas!$C$2:$C$3001,$B5,Vendas!$AK$2:$AK$3001,"Validado")) | J5: =IF(C5=0,"-",_xlfn.MAXIFS(Vendas!$Z$2:$Z$3001,Vendas!$B$2:$B$3001,$A5,Vendas!$C$2:$C$3001,$B5,Vendas!$AK$2:$AK$3001,"Validado"))
A6: São Sebastião | B6: Jaraguá | C6: =COUNTIFS(Vendas!$B$2:$B$3001,$A6,Vendas!$C$2:$C$3001,$B6,Vendas!$AK$2:$AK$3001,"Validado") | D6: {=IF(C6=0,"-",MEDIAN(IF((Vendas!$B$2:$B$3001=$A6)*(Vendas!$C$2:$C$3001=$B6)*(Vendas!$AK$2:$AK$3001="Validado")*ISNUMBER(Vendas!$M$2:$M$3001),Vendas!$M$2:$M$3001)))} | E6: =IF(C6=0,"-",_xlfn.MINIFS(Vendas!$M$2:$M$3001,Vendas!$B$2:$B$3001,$A6,Vendas!$C$2:$C$3001,$B6,Vendas!$AK$2:$AK$3001,"Validado")) | F6: =IF(C6=0,"-",_xlfn.MAXIFS(Vendas!$M$2:$M$3001,Vendas!$B$2:$B$3001,$A6,Vendas!$C$2:$C$3001,$B6,Vendas!$AK$2:$AK$3001,"Validado")) | G6: {=IF(SUMPRODUCT((Vendas!$B$2:$B$3001=$A6)*(Vendas!$C$2:$C$3001=$B6)*(Vendas!$AK$2:$AK$3001="Validado")*ISNUMBER(Vendas!$S$2:$S$3001))=0,"-",MEDIAN(IF((Vendas!$B$2:$B$3001=$A6)*(Vendas!$C$2:$C$3001=$B6)*(Vendas!$AK$2:$AK$3001="Validado")*ISNUMBER(Vendas!$S$2:$S$3001),Vendas!$S$2:$S$3001)))} | H6: =COUNTIFS(Vendas!$B$2:$B$3001,$A6,Vendas!$C$2:$C$3001,$B6,Vendas!$AK$2:$AK$3001,"Validado",Vendas!$T$2:$T$3001,"Valor*") | I6: =IF(C6=0,"-",_xlfn.MINIFS(Vendas!$Z$2:$Z$3001,Vendas!$B$2:$B$3001,$A6,Vendas!$C$2:$C$3001,$B6,Vendas!$AK$2:$AK$3001,"Validado")) | J6: =IF(C6=0,"-",_xlfn.MAXIFS(Vendas!$Z$2:$Z$3001,Vendas!$B$2:$B$3001,$A6,Vendas!$C$2:$C$3001,$B6,Vendas!$AK$2:$AK$3001,"Validado"))
A7: São Sebastião | B7: Cigarras | C7: =COUNTIFS(Vendas!$B$2:$B$3001,$A7,Vendas!$C$2:$C$3001,$B7,Vendas!$AK$2:$AK$3001,"Validado") | D7: {=IF(C7=0,"-",MEDIAN(IF((Vendas!$B$2:$B$3001=$A7)*(Vendas!$C$2:$C$3001=$B7)*(Vendas!$AK$2:$AK$3001="Validado")*ISNUMBER(Vendas!$M$2:$M$3001),Vendas!$M$2:$M$3001)))} | E7: =IF(C7=0,"-",_xlfn.MINIFS(Vendas!$M$2:$M$3001,Vendas!$B$2:$B$3001,$A7,Vendas!$C$2:$C$3001,$B7,Vendas!$AK$2:$AK$3001,"Validado")) | F7: =IF(C7=0,"-",_xlfn.MAXIFS(Vendas!$M$2:$M$3001,Vendas!$B$2:$B$3001,$A7,Vendas!$C$2:$C$3001,$B7,Vendas!$AK$2:$AK$3001,"Validado")) | G7: {=IF(SUMPRODUCT((Vendas!$B$2:$B$3001=$A7)*(Vendas!$C$2:$C$3001=$B7)*(Vendas!$AK$2:$AK$3001="Validado")*ISNUMBER(Vendas!$S$2:$S$3001))=0,"-",MEDIAN(IF((Vendas!$B$2:$B$3001=$A7)*(Vendas!$C$2:$C$3001=$B7)*(Vendas!$AK$2:$AK$3001="Validado")*ISNUMBER(Vendas!$S$2:$S$3001),Vendas!$S$2:$S$3001)))} | H7: =COUNTIFS(Vendas!$B$2:$B$3001,$A7,Vendas!$C$2:$C$3001,$B7,Vendas!$AK$2:$AK$3001,"Validado",Vendas!$T$2:$T$3001,"Valor*") | I7: =IF(C7=0,"-",_xlfn.MINIFS(Vendas!$Z$2:$Z$3001,Vendas!$B$2:$B$3001,$A7,Vendas!$C$2:$C$3001,$B7,Vendas!$AK$2:$AK$3001,"Validado")) | J7: =IF(C7=0,"-",_xlfn.MAXIFS(Vendas!$Z$2:$Z$3001,Vendas!$B$2:$B$3001,$A7,Vendas!$C$2:$C$3001,$B7,Vendas!$AK$2:$AK$3001,"Validado"))
A8: São Sebastião | B8: São Francisco | C8: =COUNTIFS(Vendas!$B$2:$B$3001,$A8,Vendas!$C$2:$C$3001,$B8,Vendas!$AK$2:$AK$3001,"Validado") | D8: {=IF(C8=0,"-",MEDIAN(IF((Vendas!$B$2:$B$3001=$A8)*(Vendas!$C$2:$C$3001=$B8)*(Vendas!$AK$2:$AK$3001="Validado")*ISNUMBER(Vendas!$M$2:$M$3001),Vendas!$M$2:$M$3001)))} | E8: =IF(C8=0,"-",_xlfn.MINIFS(Vendas!$M$2:$M$3001,Vendas!$B$2:$B$3001,$A8,Vendas!$C$2:$C$3001,$B8,Vendas!$AK$2:$AK$3001,"Validado")) | F8: =IF(C8=0,"-",_xlfn.MAXIFS(Vendas!$M$2:$M$3001,Vendas!$B$2:$B$3001,$A8,Vendas!$C$2:$C$3001,$B8,Vendas!$AK$2:$AK$3001,"Validado")) | G8: {=IF(SUMPRODUCT((Vendas!$B$2:$B$3001=$A8)*(Vendas!$C$2:$C$3001=$B8)*(Vendas!$AK$2:$AK$3001="Validado")*ISNUMBER(Vendas!$S$2:$S$3001))=0,"-",MEDIAN(IF((Vendas!$B$2:$B$3001=$A8)*(Vendas!$C$2:$C$3001=$B8)*(Vendas!$AK$2:$AK$3001="Validado")*ISNUMBER(Vendas!$S$2:$S$3001),Vendas!$S$2:$S$3001)))} | H8: =COUNTIFS(Vendas!$B$2:$B$3001,$A8,Vendas!$C$2:$C$3001,$B8,Vendas!$AK$2:$AK$3001,"Validado",Vendas!$T$2:$T$3001,"Valor*") | I8: =IF(C8=0,"-",_xlfn.MINIFS(Vendas!$Z$2:$Z$3001,Vendas!$B$2:$B$3001,$A8,Vendas!$C$2:$C$3001,$B8,Vendas!$AK$2:$AK$3001,"Validado")) | J8: =IF(C8=0,"-",_xlfn.MAXIFS(Vendas!$Z$2:$Z$3001,Vendas!$B$2:$B$3001,$A8,Vendas!$C$2:$C$3001,$B8,Vendas!$AK$2:$AK$3001,"Validado"))
A9: São Sebastião | B9: Morro do Abrigo | C9: =COUNTIFS(Vendas!$B$2:$B$3001,$A9,Vendas!$C$2:$C$3001,$B9,Vendas!$AK$2:$AK$3001,"Validado") | D9: {=IF(C9=0,"-",MEDIAN(IF((Vendas!$B$2:$B$3001=$A9)*(Vendas!$C$2:$C$3001=$B9)*(Vendas!$AK$2:$AK$3001="Validado")*ISNUMBER(Vendas!$M$2:$M$3001),Vendas!$M$2:$M$3001)))} | E9: =IF(C9=0,"-",_xlfn.MINIFS(Vendas!$M$2:$M$3001,Vendas!$B$2:$B$3001,$A9,Vendas!$C$2:$C$3001,$B9,Vendas!$AK$2:$AK$3001,"Validado")) | F9: =IF(C9=0,"-",_xlfn.MAXIFS(Vendas!$M$2:$M$3001,Vendas!$B$2:$B$3001,$A9,Vendas!$C$2:$C$3001,$B9,Vendas!$AK$2:$AK$3001,"Validado")) | G9: {=IF(SUMPRODUCT((Vendas!$B$2:$B$3001=$A9)*(Vendas!$C$2:$C$3001=$B9)*(Vendas!$AK$2:$AK$3001="Validado")*ISNUMBER(Vendas!$S$2:$S$3001))=0,"-",MEDIAN(IF((Vendas!$B$2:$B$3001=$A9)*(Vendas!$C$2:$C$3001=$B9)*(Vendas!$AK$2:$AK$3001="Validado")*ISNUMBER(Vendas!$S$2:$S$3001),Vendas!$S$2:$S$3001)))} | H9: =COUNTIFS(Vendas!$B$2:$B$3001,$A9,Vendas!$C$2:$C$3001,$B9,Vendas!$AK$2:$AK$3001,"Validado",Vendas!$T$2:$T$3001,"Valor*") | I9: =IF(C9=0,"-",_xlfn.MINIFS(Vendas!$Z$2:$Z$3001,Vendas!$B$2:$B$3001,$A9,Vendas!$C$2:$C$3001,$B9,Vendas!$AK$2:$AK$3001,"Validado")) | J9: =IF(C9=0,"-",_xlfn.MAXIFS(Vendas!$Z$2:$Z$3001,Vendas!$B$2:$B$3001,$A9,Vendas!$C$2:$C$3001,$B9,Vendas!$AK$2:$AK$3001,"Validado"))
A10: São Sebastião | B10: Olaria | C10: =COUNTIFS(Vendas!$B$2:$B$3001,$A10,Vendas!$C$2:$C$3001,$B10,Vendas!$AK$2:$AK$3001,"Validado") | D10: {=IF(C10=0,"-",MEDIAN(IF((Vendas!$B$2:$B$3001=$A10)*(Vendas!$C$2:$C$3001=$B10)*(Vendas!$AK$2:$AK$3001="Validado")*ISNUMBER(Vendas!$M$2:$M$3001),Vendas!$M$2:$M$3001)))} | E10: =IF(C10=0,"-",_xlfn.MINIFS(Vendas!$M$2:$M$3001,Vendas!$B$2:$B$3001,$A10,Vendas!$C$2:$C$3001,$B10,Vendas!$AK$2:$AK$3001,"Validado")) | F10: =IF(C10=0,"-",_xlfn.MAXIFS(Vendas!$M$2:$M$3001,Vendas!$B$2:$B$3001,$A10,Vendas!$C$2:$C$3001,$B10,Vendas!$AK$2:$AK$3001,"Validado")) | G10: {=IF(SUMPRODUCT((Vendas!$B$2:$B$3001=$A10)*(Vendas!$C$2:$C$3001=$B10)*(Vendas!$AK$2:$AK$3001="Validado")*ISNUMBER(Vendas!$S$2:$S$3001))=0,"-",MEDIAN(IF((Vendas!$B$2:$B$3001=$A10)*(Vendas!$C$2:$C$3001=$B10)*(Vendas!$AK$2:$AK$3001="Validado")*ISNUMBER(Vendas!$S$2:$S$3001),Vendas!$S$2:$S$3001)))} | H10: =COUNTIFS(Vendas!$B$2:$B$3001,$A10,Vendas!$C$2:$C$3001,$B10,Vendas!$AK$2:$AK$3001,"Validado",Vendas!$T$2:$T$3001,"Valor*") | I10: =IF(C10=0,"-",_xlfn.MINIFS(Vendas!$Z$2:$Z$3001,Vendas!$B$2:$B$3001,$A10,Vendas!$C$2:$C$3001,$B10,Vendas!$AK$2:$AK$3001,"Validado")) | J10: =IF(C10=0,"-",_xlfn.MAXIFS(Vendas!$Z$2:$Z$3001,Vendas!$B$2:$B$3001,$A10,Vendas!$C$2:$C$3001,$B10,Vendas!$AK$2:$AK$3001,"Validado"))
A11: São Sebastião | B11: Arrastão | C11: =COUNTIFS(Vendas!$B$2:$B$3001,$A11,Vendas!$C$2:$C$3001,$B11,Vendas!$AK$2:$AK$3001,"Validado") | D11: {=IF(C11=0,"-",MEDIAN(IF((Vendas!$B$2:$B$3001=$A11)*(Vendas!$C$2:$C$3001=$B11)*(Vendas!$AK$2:$AK$3001="Validado")*ISNUMBER(Vendas!$M$2:$M$3001),Vendas!$M$2:$M$3001)))} | E11: =IF(C11=0,"-",_xlfn.MINIFS(Vendas!$M$2:$M$3001,Vendas!$B$2:$B$3001,$A11,Vendas!$C$2:$C$3001,$B11,Vendas!$AK$2:$AK$3001,"Validado")) | F11: =IF(C11=0,"-",_xlfn.MAXIFS(Vendas!$M$2:$M$3001,Vendas!$B$2:$B$3001,$A11,Vendas!$C$2:$C$3001,$B11,Vendas!$AK$2:$AK$3001,"Validado")) | G11: {=IF(SUMPRODUCT((Vendas!$B$2:$B$3001=$A11)*(Vendas!$C$2:$C$3001=$B11)*(Vendas!$AK$2:$AK$3001="Validado")*ISNUMBER(Vendas!$S$2:$S$3001))=0,"-",MEDIAN(IF((Vendas!$B$2:$B$3001=$A11)*(Vendas!$C$2:$C$3001=$B11)*(Vendas!$AK$2:$AK$3001="Validado")*ISNUMBER(Vendas!$S$2:$S$3001),Vendas!$S$2:$S$3001)))} | H11: =COUNTIFS(Vendas!$B$2:$B$3001,$A11,Vendas!$C$2:$C$3001,$B11,Vendas!$AK$2:$AK$3001,"Validado",Vendas!$T$2:$T$3001,"Valor*") | I11: =IF(C11=0,"-",_xlfn.MINIFS(Vendas!$Z$2:$Z$3001,Vendas!$B$2:$B$3001,$A11,Vendas!$C$2:$C$3001,$B11,Vendas!$AK$2:$AK$3001,"Validado")) | J11: =IF(C11=0,"-",_xlfn.MAXIFS(Vendas!$Z$2:$Z$3001,Vendas!$B$2:$B$3001,$A11,Vendas!$C$2:$C$3001,$B11,Vendas!$AK$2:$AK$3001,"Validado"))
A12: São Sebastião | B12: Pontal da Cruz | C12: =COUNTIFS(Vendas!$B$2:$B$3001,$A12,Vendas!$C$2:$C$3001,$B12,Vendas!$AK$2:$AK$3001,"Validado") | D12: {=IF(C12=0,"-",MEDIAN(IF((Vendas!$B$2:$B$3001=$A12)*(Vendas!$C$2:$C$3001=$B12)*(Vendas!$AK$2:$AK$3001="Validado")*ISNUMBER(Vendas!$M$2:$M$3001),Vendas!$M$2:$M$3001)))} | E12: =IF(C12=0,"-",_xlfn.MINIFS(Vendas!$M$2:$M$3001,Vendas!$B$2:$B$3001,$A12,Vendas!$C$2:$C$3001,$B12,Vendas!$AK$2:$AK$3001,"Validado")) | F12: =IF(C12=0,"-",_xlfn.MAXIFS(Vendas!$M$2:$M$3001,Vendas!$B$2:$B$3001,$A12,Vendas!$C$2:$C$3001,$B12,Vendas!$AK$2:$AK$3001,"Validado")) | G12: {=IF(SUMPRODUCT((Vendas!$B$2:$B$3001=$A12)*(Vendas!$C$2:$C$3001=$B12)*(Vendas!$AK$2:$AK$3001="Validado")*ISNUMBER(Vendas!$S$2:$S$3001))=0,"-",MEDIAN(IF((Vendas!$B$2:$B$3001=$A12)*(Vendas!$C$2:$C$3001=$B12)*(Vendas!$AK$2:$AK$3001="Validado")*ISNUMBER(Vendas!$S$2:$S$3001),Vendas!$S$2:$S$3001)))} | H12: =COUNTIFS(Vendas!$B$2:$B$3001,$A12,Vendas!$C$2:$C$3001,$B12,Vendas!$AK$2:$AK$3001,"Validado",Vendas!$T$2:$T$3001,"Valor*") | I12: =IF(C12=0,"-",_xlfn.MINIFS(Vendas!$Z$2:$Z$3001,Vendas!$B$2:$B$3001,$A12,Vendas!$C$2:$C$3001,$B12,Vendas!$AK$2:$AK$3001,"Validado")) | J12: =IF(C12=0,"-",_xlfn.MAXIFS(Vendas!$Z$2:$Z$3001,Vendas!$B$2:$B$3001,$A12,Vendas!$C$2:$C$3001,$B12,Vendas!$AK$2:$AK$3001,"Validado"))
A13: São Sebastião | B13: Praia Deserta | C13: =COUNTIFS(Vendas!$B$2:$B$3001,$A13,Vendas!$C$2:$C$3001,$B13,Vendas!$AK$2:$AK$3001,"Validado") | D13: {=IF(C13=0,"-",MEDIAN(IF((Vendas!$B$2:$B$3001=$A13)*(Vendas!$C$2:$C$3001=$B13)*(Vendas!$AK$2:$AK$3001="Validado")*ISNUMBER(Vendas!$M$2:$M$3001),Vendas!$M$2:$M$3001)))} | E13: =IF(C13=0,"-",_xlfn.MINIFS(Vendas!$M$2:$M$3001,Vendas!$B$2:$B$3001,$A13,Vendas!$C$2:$C$3001,$B13,Vendas!$AK$2:$AK$3001,"Validado")) | F13: =IF(C13=0,"-",_xlfn.MAXIFS(Vendas!$M$2:$M$3001,Vendas!$B$2:$B$3001,$A13,Vendas!$C$2:$C$3001,$B13,Vendas!$AK$2:$AK$3001,"Validado")) | G13: {=IF(SUMPRODUCT((Vendas!$B$2:$B$3001=$A13)*(Vendas!$C$2:$C$3001=$B13)*(Vendas!$AK$2:$AK$3001="Validado")*ISNUMBER(Vendas!$S$2:$S$3001))=0,"-",MEDIAN(IF((Vendas!$B$2:$B$3001=$A13)*(Vendas!$C$2:$C$3001=$B13)*(Vendas!$AK$2:$AK$3001="Validado")*ISNUMBER(Vendas!$S$2:$S$3001),Vendas!$S$2:$S$3001)))} | H13: =COUNTIFS(Vendas!$B$2:$B$3001,$A13,Vendas!$C$2:$C$3001,$B13,Vendas!$AK$2:$AK$3001,"Validado",Vendas!$T$2:$T$3001,"Valor*") | I13: =IF(C13=0,"-",_xlfn.MINIFS(Vendas!$Z$2:$Z$3001,Vendas!$B$2:$B$3001,$A13,Vendas!$C$2:$C$3001,$B13,Vendas!$AK$2:$AK$3001,"Validado")) | J13: =IF(C13=0,"-",_xlfn.MAXIFS(Vendas!$Z$2:$Z$3001,Vendas!$B$2:$B$3001,$A13,Vendas!$C$2:$C$3001,$B13,Vendas!$AK$2:$AK$3001,"Validado"))
A14: São Sebastião | B14: Porto Grande | C14: =COUNTIFS(Vendas!$B$2:$B$3001,$A14,Vendas!$C$2:$C$3001,$B14,Vendas!$AK$2:$AK$3001,"Validado") | D14: {=IF(C14=0,"-",MEDIAN(IF((Vendas!$B$2:$B$3001=$A14)*(Vendas!$C$2:$C$3001=$B14)*(Vendas!$AK$2:$AK$3001="Validado")*ISNUMBER(Vendas!$M$2:$M$3001),Vendas!$M$2:$M$3001)))} | E14: =IF(C14=0,"-",_xlfn.MINIFS(Vendas!$M$2:$M$3001,Vendas!$B$2:$B$3001,$A14,Vendas!$C$2:$C$3001,$B14,Vendas!$AK$2:$AK$3001,"Validado")) | F14: =IF(C14=0,"-",_xlfn.MAXIFS(Vendas!$M$2:$M$3001,Vendas!$B$2:$B$3001,$A14,Vendas!$C$2:$C$3001,$B14,Vendas!$AK$2:$AK$3001,"Validado")) | G14: {=IF(SUMPRODUCT((Vendas!$B$2:$B$3001=$A14)*(Vendas!$C$2:$C$3001=$B14)*(Vendas!$AK$2:$AK$3001="Validado")*ISNUMBER(Vendas!$S$2:$S$3001))=0,"-",MEDIAN(IF((Vendas!$B$2:$B$3001=$A14)*(Vendas!$C$2:$C$3001=$B14)*(Vendas!$AK$2:$AK$3001="Validado")*ISNUMBER(Vendas!$S$2:$S$3001),Vendas!$S$2:$S$3001)))} | H14: =COUNTIFS(Vendas!$B$2:$B$3001,$A14,Vendas!$C$2:$C$3001,$B14,Vendas!$AK$2:$AK$3001,"Validado",Vendas!$T$2:$T$3001,"Valor*") | I14: =IF(C14=0,"-",_xlfn.MINIFS(Vendas!$Z$2:$Z$3001,Vendas!$B$2:$B$3001,$A14,Vendas!$C$2:$C$3001,$B14,Vendas!$AK$2:$AK$3001,"Validado")) | J14: =IF(C14=0,"-",_xlfn.MAXIFS(Vendas!$Z$2:$Z$3001,Vendas!$B$2:$B$3001,$A14,Vendas!$C$2:$C$3001,$B14,Vendas!$AK$2:$AK$3001,"Validado"))
A15: São Sebastião | B15: Centro | C15: =COUNTIFS(Vendas!$B$2:$B$3001,$A15,Vendas!$C$2:$C$3001,$B15,Vendas!$AK$2:$AK$3001,"Validado") | D15: {=IF(C15=0,"-",MEDIAN(IF((Vendas!$B$2:$B$3001=$A15)*(Vendas!$C$2:$C$3001=$B15)*(Vendas!$AK$2:$AK$3001="Validado")*ISNUMBER(Vendas!$M$2:$M$3001),Vendas!$M$2:$M$3001)))} | E15: =IF(C15=0,"-",_xlfn.MINIFS(Vendas!$M$2:$M$3001,Vendas!$B$2:$B$3001,$A15,Vendas!$C$2:$C$3001,$B15,Vendas!$AK$2:$AK$3001,"Validado")) | F15: =IF(C15=0,"-",_xlfn.MAXIFS(Vendas!$M$2:$M$3001,Vendas!$B$2:$B$3001,$A15,Vendas!$C$2:$C$3001,$B15,Vendas!$AK$2:$AK$3001,"Validado")) | G15: {=IF(SUMPRODUCT((Vendas!$B$2:$B$3001=$A15)*(Vendas!$C$2:$C$3001=$B15)*(Vendas!$AK$2:$AK$3001="Validado")*ISNUMBER(Vendas!$S$2:$S$3001))=0,"-",MEDIAN(IF((Vendas!$B$2:$B$3001=$A15)*(Vendas!$C$2:$C$3001=$B15)*(Vendas!$AK$2:$AK$3001="Validado")*ISNUMBER(Vendas!$S$2:$S$3001),Vendas!$S$2:$S$3001)))} | H15: =COUNTIFS(Vendas!$B$2:$B$3001,$A15,Vendas!$C$2:$C$3001,$B15,Vendas!$AK$2:$AK$3001,"Validado",Vendas!$T$2:$T$3001,"Valor*") | I15: =IF(C15=0,"-",_xlfn.MINIFS(Vendas!$Z$2:$Z$3001,Vendas!$B$2:$B$3001,$A15,Vendas!$C$2:$C$3001,$B15,Vendas!$AK$2:$AK$3001,"Validado")) | J15: =IF(C15=0,"-",_xlfn.MAXIFS(Vendas!$Z$2:$Z$3001,Vendas!$B$2:$B$3001,$A15,Vendas!$C$2:$C$3001,$B15,Vendas!$AK$2:$AK$3001,"Validado"))
A16: São Sebastião | B16: Topolândia | C16: =COUNTIFS(Vendas!$B$2:$B$3001,$A16,Vendas!$C$2:$C$3001,$B16,Vendas!$AK$2:$AK$3001,"Validado") | D16: {=IF(C16=0,"-",MEDIAN(IF((Vendas!$B$2:$B$3001=$A16)*(Vendas!$C$2:$C$3001=$B16)*(Vendas!$AK$2:$AK$3001="Validado")*ISNUMBER(Vendas!$M$2:$M$3001),Vendas!$M$2:$M$3001)))} | E16: =IF(C16=0,"-",_xlfn.MINIFS(Vendas!$M$2:$M$3001,Vendas!$B$2:$B$3001,$A16,Vendas!$C$2:$C$3001,$B16,Vendas!$AK$2:$AK$3001,"Validado")) | F16: =IF(C16=0,"-",_xlfn.MAXIFS(Vendas!$M$2:$M$3001,Vendas!$B$2:$B$3001,$A16,Vendas!$C$2:$C$3001,$B16,Vendas!$AK$2:$AK$3001,"Validado")) | G16: {=IF(SUMPRODUCT((Vendas!$B$2:$B$3001=$A16)*(Vendas!$C$2:$C$3001=$B16)*(Vendas!$AK$2:$AK$3001="Validado")*ISNUMBER(Vendas!$S$2:$S$3001))=0,"-",MEDIAN(IF((Vendas!$B$2:$B$3001=$A16)*(Vendas!$C$2:$C$3001=$B16)*(Vendas!$AK$2:$AK$3001="Validado")*ISNUMBER(Vendas!$S$2:$S$3001),Vendas!$S$2:$S$3001)))} | H16: =COUNTIFS(Vendas!$B$2:$B$3001,$A16,Vendas!$C$2:$C$3001,$B16,Vendas!$AK$2:$AK$3001,"Validado",Vendas!$T$2:$T$3001,"Valor*") | I16: =IF(C16=0,"-",_xlfn.MINIFS(Vendas!$Z$2:$Z$3001,Vendas!$B$2:$B$3001,$A16,Vendas!$C$2:$C$3001,$B16,Vendas!$AK$2:$AK$3001,"Validado")) | J16: =IF(C16=0,"-",_xlfn.MAXIFS(Vendas!$Z$2:$Z$3001,Vendas!$B$2:$B$3001,$A16,Vendas!$C$2:$C$3001,$B16,Vendas!$AK$2:$AK$3001,"Validado"))
... A40: São Sebastião | B40: Engenho | C40: =COUNTIFS(Vendas!$B$2:$B$3001,$A40,Vendas!$C$2:$C$3001,$B40,Vendas!$AK$2:$AK$3001,"Validado") | D40: {=IF(C40=0,"-",MEDIAN(IF((Vendas!$B$2:$B$3001=$A40)*(Vendas!$C$2:$C$3001=$B40)*(Vendas!$AK$2:$AK$3001="Validado")*ISNUMBER(Vendas!$M$2:$M$3001),Vendas!$M$2:$M$3001)))} | E40: =IF(C40=0,"-",_xlfn.MINIFS(Vendas!$M$2:$M$3001,Vendas!$B$2:$B$3001,$A40,Vendas!$C$2:$C$3001,$B40,Vendas!$AK$2:$AK$3001,"Validado")) | F40: =IF(C40=0,"-",_xlfn.MAXIFS(Vendas!$M$2:$M$3001,Vendas!$B$2:$B$3001,$A40,Vendas!$C$2:$C$3001,$B40,Vendas!$AK$2:$AK$3001,"Validado")) | G40: {=IF(SUMPRODUCT((Vendas!$B$2:$B$3001=$A40)*(Vendas!$C$2:$C$3001=$B40)*(Vendas!$AK$2:$AK$3001="Validado")*ISNUMBER(Vendas!$S$2:$S$3001))=0,"-",MEDIAN(IF((Vendas!$B$2:$B$3001=$A40)*(Vendas!$C$2:$C$3001=$B40)*(Vendas!$AK$2:$AK$3001="Validado")*ISNUMBER(Vendas!$S$2:$S$3001),Vendas!$S$2:$S$3001)))} | H40: =COUNTIFS(Vendas!$B$2:$B$3001,$A40,Vendas!$C$2:$C$3001,$B40,Vendas!$AK$2:$AK$3001,"Validado",Vendas!$T$2:$T$3001,"Valor*") | I40: =IF(C40=0,"-",_xlfn.MINIFS(Vendas!$Z$2:$Z$3001,Vendas!$B$2:$B$3001,$A40,Vendas!$C$2:$C$3001,$B40,Vendas!$AK$2:$AK$3001,"Validado")) | J40: =IF(C40=0,"-",_xlfn.MAXIFS(Vendas!$Z$2:$Z$3001,Vendas!$B$2:$B$3001,$A40,Vendas!$C$2:$C$3001,$B40,Vendas!$AK$2:$AK$3001,"Validado"))
A41: São Sebastião | B41: TOTAL DA CIDADE | C41: =COUNTIFS(Vendas!$B$2:$B$3001,$A41,Vendas!$AK$2:$AK$3001,"Validado") | D41: {=IF(C41=0,"-",MEDIAN(IF((Vendas!$B$2:$B$3001=$A41)*(Vendas!$AK$2:$AK$3001="Validado")*ISNUMBER(Vendas!$M$2:$M$3001),Vendas!$M$2:$M$3001)))} | E41: =IF(C41=0,"-",_xlfn.MINIFS(Vendas!$M$2:$M$3001,Vendas!$B$2:$B$3001,$A41,Vendas!$AK$2:$AK$3001,"Validado")) | F41: =IF(C41=0,"-",_xlfn.MAXIFS(Vendas!$M$2:$M$3001,Vendas!$B$2:$B$3001,$A41,Vendas!$AK$2:$AK$3001,"Validado")) | G41: {=IF(SUMPRODUCT((Vendas!$B$2:$B$3001=$A41)*(Vendas!$AK$2:$AK$3001="Validado")*ISNUMBER(Vendas!$S$2:$S$3001))=0,"-",MEDIAN(IF((Vendas!$B$2:$B$3001=$A41)*(Vendas!$AK$2:$AK$3001="Validado")*ISNUMBER(Vendas!$S$2:$S$3001),Vendas!$S$2:$S$3001)))} | H41: =COUNTIFS(Vendas!$B$2:$B$3001,$A41,Vendas!$AK$2:$AK$3001,"Validado",Vendas!$T$2:$T$3001,"Valor*") | I41: =IF(C41=0,"-",_xlfn.MINIFS(Vendas!$Z$2:$Z$3001,Vendas!$B$2:$B$3001,$A41,Vendas!$AK$2:$AK$3001,"Validado")) | J41: =IF(C41=0,"-",_xlfn.MAXIFS(Vendas!$Z$2:$Z$3001,Vendas!$B$2:$B$3001,$A41,Vendas!$AK$2:$AK$3001,"Validado"))
A43: Bertioga | B43: Caiubura | C43: =COUNTIFS(Vendas!$B$2:$B$3001,$A43,Vendas!$C$2:$C$3001,$B43,Vendas!$AK$2:$AK$3001,"Validado") | D43: {=IF(C43=0,"-",MEDIAN(IF((Vendas!$B$2:$B$3001=$A43)*(Vendas!$C$2:$C$3001=$B43)*(Vendas!$AK$2:$AK$3001="Validado")*ISNUMBER(Vendas!$M$2:$M$3001),Vendas!$M$2:$M$3001)))} | E43: =IF(C43=0,"-",_xlfn.MINIFS(Vendas!$M$2:$M$3001,Vendas!$B$2:$B$3001,$A43,Vendas!$C$2:$C$3001,$B43,Vendas!$AK$2:$AK$3001,"Validado")) | F43: =IF(C43=0,"-",_xlfn.MAXIFS(Vendas!$M$2:$M$3001,Vendas!$B$2:$B$3001,$A43,Vendas!$C$2:$C$3001,$B43,Vendas!$AK$2:$AK$3001,"Validado")) | G43: {=IF(SUMPRODUCT((Vendas!$B$2:$B$3001=$A43)*(Vendas!$C$2:$C$3001=$B43)*(Vendas!$AK$2:$AK$3001="Validado")*ISNUMBER(Vendas!$S$2:$S$3001))=0,"-",MEDIAN(IF((Vendas!$B$2:$B$3001=$A43)*(Vendas!$C$2:$C$3001=$B43)*(Vendas!$AK$2:$AK$3001="Validado")*ISNUMBER(Vendas!$S$2:$S$3001),Vendas!$S$2:$S$3001)))} | H43: =COUNTIFS(Vendas!$B$2:$B$3001,$A43,Vendas!$C$2:$C$3001,$B43,Vendas!$AK$2:$AK$3001,"Validado",Vendas!$T$2:$T$3001,"Valor*") | I43: =IF(C43=0,"-",_xlfn.MINIFS(Vendas!$Z$2:$Z$3001,Vendas!$B$2:$B$3001,$A43,Vendas!$C$2:$C$3001,$B43,Vendas!$AK$2:$AK$3001,"Validado")) | J43: =IF(C43=0,"-",_xlfn.MAXIFS(Vendas!$Z$2:$Z$3001,Vendas!$B$2:$B$3001,$A43,Vendas!$C$2:$C$3001,$B43,Vendas!$AK$2:$AK$3001,"Validado"))
A44: Bertioga | B44: São João | C44: =COUNTIFS(Vendas!$B$2:$B$3001,$A44,Vendas!$C$2:$C$3001,$B44,Vendas!$AK$2:$AK$3001,"Validado") | D44: {=IF(C44=0,"-",MEDIAN(IF((Vendas!$B$2:$B$3001=$A44)*(Vendas!$C$2:$C$3001=$B44)*(Vendas!$AK$2:$AK$3001="Validado")*ISNUMBER(Vendas!$M$2:$M$3001),Vendas!$M$2:$M$3001)))} | E44: =IF(C44=0,"-",_xlfn.MINIFS(Vendas!$M$2:$M$3001,Vendas!$B$2:$B$3001,$A44,Vendas!$C$2:$C$3001,$B44,Vendas!$AK$2:$AK$3001,"Validado")) | F44: =IF(C44=0,"-",_xlfn.MAXIFS(Vendas!$M$2:$M$3001,Vendas!$B$2:$B$3001,$A44,Vendas!$C$2:$C$3001,$B44,Vendas!$AK$2:$AK$3001,"Validado")) | G44: {=IF(SUMPRODUCT((Vendas!$B$2:$B$3001=$A44)*(Vendas!$C$2:$C$3001=$B44)*(Vendas!$AK$2:$AK$3001="Validado")*ISNUMBER(Vendas!$S$2:$S$3001))=0,"-",MEDIAN(IF((Vendas!$B$2:$B$3001=$A44)*(Vendas!$C$2:$C$3001=$B44)*(Vendas!$AK$2:$AK$3001="Validado")*ISNUMBER(Vendas!$S$2:$S$3001),Vendas!$S$2:$S$3001)))} | H44: =COUNTIFS(Vendas!$B$2:$B$3001,$A44,Vendas!$C$2:$C$3001,$B44,Vendas!$AK$2:$AK$3001,"Validado",Vendas!$T$2:$T$3001,"Valor*") | I44: =IF(C44=0,"-",_xlfn.MINIFS(Vendas!$Z$2:$Z$3001,Vendas!$B$2:$B$3001,$A44,Vendas!$C$2:$C$3001,$B44,Vendas!$AK$2:$AK$3001,"Validado")) | J44: =IF(C44=0,"-",_xlfn.MAXIFS(Vendas!$Z$2:$Z$3001,Vendas!$B$2:$B$3001,$A44,Vendas!$C$2:$C$3001,$B44,Vendas!$AK$2:$AK$3001,"Validado"))
A45: Bertioga | B45: Centro | C45: =COUNTIFS(Vendas!$B$2:$B$3001,$A45,Vendas!$C$2:$C$3001,$B45,Vendas!$AK$2:$AK$3001,"Validado") | D45: {=IF(C45=0,"-",MEDIAN(IF((Vendas!$B$2:$B$3001=$A45)*(Vendas!$C$2:$C$3001=$B45)*(Vendas!$AK$2:$AK$3001="Validado")*ISNUMBER(Vendas!$M$2:$M$3001),Vendas!$M$2:$M$3001)))} | E45: =IF(C45=0,"-",_xlfn.MINIFS(Vendas!$M$2:$M$3001,Vendas!$B$2:$B$3001,$A45,Vendas!$C$2:$C$3001,$B45,Vendas!$AK$2:$AK$3001,"Validado")) | F45: =IF(C45=0,"-",_xlfn.MAXIFS(Vendas!$M$2:$M$3001,Vendas!$B$2:$B$3001,$A45,Vendas!$C$2:$C$3001,$B45,Vendas!$AK$2:$AK$3001,"Validado")) | G45: {=IF(SUMPRODUCT((Vendas!$B$2:$B$3001=$A45)*(Vendas!$C$2:$C$3001=$B45)*(Vendas!$AK$2:$AK$3001="Validado")*ISNUMBER(Vendas!$S$2:$S$3001))=0,"-",MEDIAN(IF((Vendas!$B$2:$B$3001=$A45)*(Vendas!$C$2:$C$3001=$B45)*(Vendas!$AK$2:$AK$3001="Validado")*ISNUMBER(Vendas!$S$2:$S$3001),Vendas!$S$2:$S$3001)))} | H45: =COUNTIFS(Vendas!$B$2:$B$3001,$A45,Vendas!$C$2:$C$3001,$B45,Vendas!$AK$2:$AK$3001,"Validado",Vendas!$T$2:$T$3001,"Valor*") | I45: =IF(C45=0,"-",_xlfn.MINIFS(Vendas!$Z$2:$Z$3001,Vendas!$B$2:$B$3001,$A45,Vendas!$C$2:$C$3001,$B45,Vendas!$AK$2:$AK$3001,"Validado")) | J45: =IF(C45=0,"-",_xlfn.MAXIFS(Vendas!$Z$2:$Z$3001,Vendas!$B$2:$B$3001,$A45,Vendas!$C$2:$C$3001,$B45,Vendas!$AK$2:$AK$3001,"Validado"))
A46: Bertioga | B46: Jardim Vicente de Carvalho | C46: =COUNTIFS(Vendas!$B$2:$B$3001,$A46,Vendas!$C$2:$C$3001,$B46,Vendas!$AK$2:$AK$3001,"Validado") | D46: {=IF(C46=0,"-",MEDIAN(IF((Vendas!$B$2:$B$3001=$A46)*(Vendas!$C$2:$C$3001=$B46)*(Vendas!$AK$2:$AK$3001="Validado")*ISNUMBER(Vendas!$M$2:$M$3001),Vendas!$M$2:$M$3001)))} | E46: =IF(C46=0,"-",_xlfn.MINIFS(Vendas!$M$2:$M$3001,Vendas!$B$2:$B$3001,$A46,Vendas!$C$2:$C$3001,$B46,Vendas!$AK$2:$AK$3001,"Validado")) | F46: =IF(C46=0,"-",_xlfn.MAXIFS(Vendas!$M$2:$M$3001,Vendas!$B$2:$B$3001,$A46,Vendas!$C$2:$C$3001,$B46,Vendas!$AK$2:$AK$3001,"Validado")) | G46: {=IF(SUMPRODUCT((Vendas!$B$2:$B$3001=$A46)*(Vendas!$C$2:$C$3001=$B46)*(Vendas!$AK$2:$AK$3001="Validado")*ISNUMBER(Vendas!$S$2:$S$3001))=0,"-",MEDIAN(IF((Vendas!$B$2:$B$3001=$A46)*(Vendas!$C$2:$C$3001=$B46)*(Vendas!$AK$2:$AK$3001="Validado")*ISNUMBER(Vendas!$S$2:$S$3001),Vendas!$S$2:$S$3001)))} | H46: =COUNTIFS(Vendas!$B$2:$B$3001,$A46,Vendas!$C$2:$C$3001,$B46,Vendas!$AK$2:$AK$3001,"Validado",Vendas!$T$2:$T$3001,"Valor*") | I46: =IF(C46=0,"-",_xlfn.MINIFS(Vendas!$Z$2:$Z$3001,Vendas!$B$2:$B$3001,$A46,Vendas!$C$2:$C$3001,$B46,Vendas!$AK$2:$AK$3001,"Validado")) | J46: =IF(C46=0,"-",_xlfn.MAXIFS(Vendas!$Z$2:$Z$3001,Vendas!$B$2:$B$3001,$A46,Vendas!$C$2:$C$3001,$B46,Vendas!$AK$2:$AK$3001,"Validado"))
A47: Bertioga | B47: Albatróz | C47: =COUNTIFS(Vendas!$B$2:$B$3001,$A47,Vendas!$C$2:$C$3001,$B47,Vendas!$AK$2:$AK$3001,"Validado") | D47: {=IF(C47=0,"-",MEDIAN(IF((Vendas!$B$2:$B$3001=$A47)*(Vendas!$C$2:$C$3001=$B47)*(Vendas!$AK$2:$AK$3001="Validado")*ISNUMBER(Vendas!$M$2:$M$3001),Vendas!$M$2:$M$3001)))} | E47: =IF(C47=0,"-",_xlfn.MINIFS(Vendas!$M$2:$M$3001,Vendas!$B$2:$B$3001,$A47,Vendas!$C$2:$C$3001,$B47,Vendas!$AK$2:$AK$3001,"Validado")) | F47: =IF(C47=0,"-",_xlfn.MAXIFS(Vendas!$M$2:$M$3001,Vendas!$B$2:$B$3001,$A47,Vendas!$C$2:$C$3001,$B47,Vendas!$AK$2:$AK$3001,"Validado")) | G47: {=IF(SUMPRODUCT((Vendas!$B$2:$B$3001=$A47)*(Vendas!$C$2:$C$3001=$B47)*(Vendas!$AK$2:$AK$3001="Validado")*ISNUMBER(Vendas!$S$2:$S$3001))=0,"-",MEDIAN(IF((Vendas!$B$2:$B$3001=$A47)*(Vendas!$C$2:$C$3001=$B47)*(Vendas!$AK$2:$AK$3001="Validado")*ISNUMBER(Vendas!$S$2:$S$3001),Vendas!$S$2:$S$3001)))} | H47: =COUNTIFS(Vendas!$B$2:$B$3001,$A47,Vendas!$C$2:$C$3001,$B47,Vendas!$AK$2:$AK$3001,"Validado",Vendas!$T$2:$T$3001,"Valor*") | I47: =IF(C47=0,"-",_xlfn.MINIFS(Vendas!$Z$2:$Z$3001,Vendas!$B$2:$B$3001,$A47,Vendas!$C$2:$C$3001,$B47,Vendas!$AK$2:$AK$3001,"Validado")) | J47: =IF(C47=0,"-",_xlfn.MAXIFS(Vendas!$Z$2:$Z$3001,Vendas!$B$2:$B$3001,$A47,Vendas!$C$2:$C$3001,$B47,Vendas!$AK$2:$AK$3001,"Validado"))
A48: Bertioga | B48: Maitinga | C48: =COUNTIFS(Vendas!$B$2:$B$3001,$A48,Vendas!$C$2:$C$3001,$B48,Vendas!$AK$2:$AK$3001,"Validado") | D48: {=IF(C48=0,"-",MEDIAN(IF((Vendas!$B$2:$B$3001=$A48)*(Vendas!$C$2:$C$3001=$B48)*(Vendas!$AK$2:$AK$3001="Validado")*ISNUMBER(Vendas!$M$2:$M$3001),Vendas!$M$2:$M$3001)))} | E48: =IF(C48=0,"-",_xlfn.MINIFS(Vendas!$M$2:$M$3001,Vendas!$B$2:$B$3001,$A48,Vendas!$C$2:$C$3001,$B48,Vendas!$AK$2:$AK$3001,"Validado")) | F48: =IF(C48=0,"-",_xlfn.MAXIFS(Vendas!$M$2:$M$3001,Vendas!$B$2:$B$3001,$A48,Vendas!$C$2:$C$3001,$B48,Vendas!$AK$2:$AK$3001,"Validado")) | G48: {=IF(SUMPRODUCT((Vendas!$B$2:$B$3001=$A48)*(Vendas!$C$2:$C$3001=$B48)*(Vendas!$AK$2:$AK$3001="Validado")*ISNUMBER(Vendas!$S$2:$S$3001))=0,"-",MEDIAN(IF((Vendas!$B$2:$B$3001=$A48)*(Vendas!$C$2:$C$3001=$B48)*(Vendas!$AK$2:$AK$3001="Validado")*ISNUMBER(Vendas!$S$2:$S$3001),Vendas!$S$2:$S$3001)))} | H48: =COUNTIFS(Vendas!$B$2:$B$3001,$A48,Vendas!$C$2:$C$3001,$B48,Vendas!$AK$2:$AK$3001,"Validado",Vendas!$T$2:$T$3001,"Valor*") | I48: =IF(C48=0,"-",_xlfn.MINIFS(Vendas!$Z$2:$Z$3001,Vendas!$B$2:$B$3001,$A48,Vendas!$C$2:$C$3001,$B48,Vendas!$AK$2:$AK$3001,"Validado")) | J48: =IF(C48=0,"-",_xlfn.MAXIFS(Vendas!$Z$2:$Z$3001,Vendas!$B$2:$B$3001,$A48,Vendas!$C$2:$C$3001,$B48,Vendas!$AK$2:$AK$3001,"Validado"))
A49: Bertioga | B49: Rio da Praia | C49: =COUNTIFS(Vendas!$B$2:$B$3001,$A49,Vendas!$C$2:$C$3001,$B49,Vendas!$AK$2:$AK$3001,"Validado") | D49: {=IF(C49=0,"-",MEDIAN(IF((Vendas!$B$2:$B$3001=$A49)*(Vendas!$C$2:$C$3001=$B49)*(Vendas!$AK$2:$AK$3001="Validado")*ISNUMBER(Vendas!$M$2:$M$3001),Vendas!$M$2:$M$3001)))} | E49: =IF(C49=0,"-",_xlfn.MINIFS(Vendas!$M$2:$M$3001,Vendas!$B$2:$B$3001,$A49,Vendas!$C$2:$C$3001,$B49,Vendas!$AK$2:$AK$3001,"Validado")) | F49: =IF(C49=0,"-",_xlfn.MAXIFS(Vendas!$M$2:$M$3001,Vendas!$B$2:$B$3001,$A49,Vendas!$C$2:$C$3001,$B49,Vendas!$AK$2:$AK$3001,"Validado")) | G49: {=IF(SUMPRODUCT((Vendas!$B$2:$B$3001=$A49)*(Vendas!$C$2:$C$3001=$B49)*(Vendas!$AK$2:$AK$3001="Validado")*ISNUMBER(Vendas!$S$2:$S$3001))=0,"-",MEDIAN(IF((Vendas!$B$2:$B$3001=$A49)*(Vendas!$C$2:$C$3001=$B49)*(Vendas!$AK$2:$AK$3001="Validado")*ISNUMBER(Vendas!$S$2:$S$3001),Vendas!$S$2:$S$3001)))} | H49: =COUNTIFS(Vendas!$B$2:$B$3001,$A49,Vendas!$C$2:$C$3001,$B49,Vendas!$AK$2:$AK$3001,"Validado",Vendas!$T$2:$T$3001,"Valor*") | I49: =IF(C49=0,"-",_xlfn.MINIFS(Vendas!$Z$2:$Z$3001,Vendas!$B$2:$B$3001,$A49,Vendas!$C$2:$C$3001,$B49,Vendas!$AK$2:$AK$3001,"Validado")) | J49: =IF(C49=0,"-",_xlfn.MAXIFS(Vendas!$Z$2:$Z$3001,Vendas!$B$2:$B$3001,$A49,Vendas!$C$2:$C$3001,$B49,Vendas!$AK$2:$AK$3001,"Validado"))
A50: Bertioga | B50: Buriqui Costa Nativa (Brasfanta) | C50: =COUNTIFS(Vendas!$B$2:$B$3001,$A50,Vendas!$C$2:$C$3001,$B50,Vendas!$AK$2:$AK$3001,"Validado") | D50: {=IF(C50=0,"-",MEDIAN(IF((Vendas!$B$2:$B$3001=$A50)*(Vendas!$C$2:$C$3001=$B50)*(Vendas!$AK$2:$AK$3001="Validado")*ISNUMBER(Vendas!$M$2:$M$3001),Vendas!$M$2:$M$3001)))} | E50: =IF(C50=0,"-",_xlfn.MINIFS(Vendas!$M$2:$M$3001,Vendas!$B$2:$B$3001,$A50,Vendas!$C$2:$C$3001,$B50,Vendas!$AK$2:$AK$3001,"Validado")) | F50: =IF(C50=0,"-",_xlfn.MAXIFS(Vendas!$M$2:$M$3001,Vendas!$B$2:$B$3001,$A50,Vendas!$C$2:$C$3001,$B50,Vendas!$AK$2:$AK$3001,"Validado")) | G50: {=IF(SUMPRODUCT((Vendas!$B$2:$B$3001=$A50)*(Vendas!$C$2:$C$3001=$B50)*(Vendas!$AK$2:$AK$3001="Validado")*ISNUMBER(Vendas!$S$2:$S$3001))=0,"-",MEDIAN(IF((Vendas!$B$2:$B$3001=$A50)*(Vendas!$C$2:$C$3001=$B50)*(Vendas!$AK$2:$AK$3001="Validado")*ISNUMBER(Vendas!$S$2:$S$3001),Vendas!$S$2:$S$3001)))} | H50: =COUNTIFS(Vendas!$B$2:$B$3001,$A50,Vendas!$C$2:$C$3001,$B50,Vendas!$AK$2:$AK$3001,"Validado",Vendas!$T$2:$T$3001,"Valor*") | I50: =IF(C50=0,"-",_xlfn.MINIFS(Vendas!$Z$2:$Z$3001,Vendas!$B$2:$B$3001,$A50,Vendas!$C$2:$C$3001,$B50,Vendas!$AK$2:$AK$3001,"Validado")) | J50: =IF(C50=0,"-",_xlfn.MAXIFS(Vendas!$Z$2:$Z$3001,Vendas!$B$2:$B$3001,$A50,Vendas!$C$2:$C$3001,$B50,Vendas!$AK$2:$AK$3001,"Validado"))
A51: Bertioga | B51: Jardim Raphael | C51: =COUNTIFS(Vendas!$B$2:$B$3001,$A51,Vendas!$C$2:$C$3001,$B51,Vendas!$AK$2:$AK$3001,"Validado") | D51: {=IF(C51=0,"-",MEDIAN(IF((Vendas!$B$2:$B$3001=$A51)*(Vendas!$C$2:$C$3001=$B51)*(Vendas!$AK$2:$AK$3001="Validado")*ISNUMBER(Vendas!$M$2:$M$3001),Vendas!$M$2:$M$3001)))} | E51: =IF(C51=0,"-",_xlfn.MINIFS(Vendas!$M$2:$M$3001,Vendas!$B$2:$B$3001,$A51,Vendas!$C$2:$C$3001,$B51,Vendas!$AK$2:$AK$3001,"Validado")) | F51: =IF(C51=0,"-",_xlfn.MAXIFS(Vendas!$M$2:$M$3001,Vendas!$B$2:$B$3001,$A51,Vendas!$C$2:$C$3001,$B51,Vendas!$AK$2:$AK$3001,"Validado")) | G51: {=IF(SUMPRODUCT((Vendas!$B$2:$B$3001=$A51)*(Vendas!$C$2:$C$3001=$B51)*(Vendas!$AK$2:$AK$3001="Validado")*ISNUMBER(Vendas!$S$2:$S$3001))=0,"-",MEDIAN(IF((Vendas!$B$2:$B$3001=$A51)*(Vendas!$C$2:$C$3001=$B51)*(Vendas!$AK$2:$AK$3001="Validado")*ISNUMBER(Vendas!$S$2:$S$3001),Vendas!$S$2:$S$3001)))} | H51: =COUNTIFS(Vendas!$B$2:$B$3001,$A51,Vendas!$C$2:$C$3001,$B51,Vendas!$AK$2:$AK$3001,"Validado",Vendas!$T$2:$T$3001,"Valor*") | I51: =IF(C51=0,"-",_xlfn.MINIFS(Vendas!$Z$2:$Z$3001,Vendas!$B$2:$B$3001,$A51,Vendas!$C$2:$C$3001,$B51,Vendas!$AK$2:$AK$3001,"Validado")) | J51: =IF(C51=0,"-",_xlfn.MAXIFS(Vendas!$Z$2:$Z$3001,Vendas!$B$2:$B$3001,$A51,Vendas!$C$2:$C$3001,$B51,Vendas!$AK$2:$AK$3001,"Validado"))
A52: Bertioga | B52: Bairro Chácaras | C52: =COUNTIFS(Vendas!$B$2:$B$3001,$A52,Vendas!$C$2:$C$3001,$B52,Vendas!$AK$2:$AK$3001,"Validado") | D52: {=IF(C52=0,"-",MEDIAN(IF((Vendas!$B$2:$B$3001=$A52)*(Vendas!$C$2:$C$3001=$B52)*(Vendas!$AK$2:$AK$3001="Validado")*ISNUMBER(Vendas!$M$2:$M$3001),Vendas!$M$2:$M$3001)))} | E52: =IF(C52=0,"-",_xlfn.MINIFS(Vendas!$M$2:$M$3001,Vendas!$B$2:$B$3001,$A52,Vendas!$C$2:$C$3001,$B52,Vendas!$AK$2:$AK$3001,"Validado")) | F52: =IF(C52=0,"-",_xlfn.MAXIFS(Vendas!$M$2:$M$3001,Vendas!$B$2:$B$3001,$A52,Vendas!$C$2:$C$3001,$B52,Vendas!$AK$2:$AK$3001,"Validado")) | G52: {=IF(SUMPRODUCT((Vendas!$B$2:$B$3001=$A52)*(Vendas!$C$2:$C$3001=$B52)*(Vendas!$AK$2:$AK$3001="Validado")*ISNUMBER(Vendas!$S$2:$S$3001))=0,"-",MEDIAN(IF((Vendas!$B$2:$B$3001=$A52)*(Vendas!$C$2:$C$3001=$B52)*(Vendas!$AK$2:$AK$3001="Validado")*ISNUMBER(Vendas!$S$2:$S$3001),Vendas!$S$2:$S$3001)))} | H52: =COUNTIFS(Vendas!$B$2:$B$3001,$A52,Vendas!$C$2:$C$3001,$B52,Vendas!$AK$2:$AK$3001,"Validado",Vendas!$T$2:$T$3001,"Valor*") | I52: =IF(C52=0,"-",_xlfn.MINIFS(Vendas!$Z$2:$Z$3001,Vendas!$B$2:$B$3001,$A52,Vendas!$C$2:$C$3001,$B52,Vendas!$AK$2:$AK$3001,"Validado")) | J52: =IF(C52=0,"-",_xlfn.MAXIFS(Vendas!$Z$2:$Z$3001,Vendas!$B$2:$B$3001,$A52,Vendas!$C$2:$C$3001,$B52,Vendas!$AK$2:$AK$3001,"Validado"))
A53: Bertioga | B53: Vista Linda | C53: =COUNTIFS(Vendas!$B$2:$B$3001,$A53,Vendas!$C$2:$C$3001,$B53,Vendas!$AK$2:$AK$3001,"Validado") | D53: {=IF(C53=0,"-",MEDIAN(IF((Vendas!$B$2:$B$3001=$A53)*(Vendas!$C$2:$C$3001=$B53)*(Vendas!$AK$2:$AK$3001="Validado")*ISNUMBER(Vendas!$M$2:$M$3001),Vendas!$M$2:$M$3001)))} | E53: =IF(C53=0,"-",_xlfn.MINIFS(Vendas!$M$2:$M$3001,Vendas!$B$2:$B$3001,$A53,Vendas!$C$2:$C$3001,$B53,Vendas!$AK$2:$AK$3001,"Validado")) | F53: =IF(C53=0,"-",_xlfn.MAXIFS(Vendas!$M$2:$M$3001,Vendas!$B$2:$B$3001,$A53,Vendas!$C$2:$C$3001,$B53,Vendas!$AK$2:$AK$3001,"Validado")) | G53: {=IF(SUMPRODUCT((Vendas!$B$2:$B$3001=$A53)*(Vendas!$C$2:$C$3001=$B53)*(Vendas!$AK$2:$AK$3001="Validado")*ISNUMBER(Vendas!$S$2:$S$3001))=0,"-",MEDIAN(IF((Vendas!$B$2:$B$3001=$A53)*(Vendas!$C$2:$C$3001=$B53)*(Vendas!$AK$2:$AK$3001="Validado")*ISNUMBER(Vendas!$S$2:$S$3001),Vendas!$S$2:$S$3001)))} | H53: =COUNTIFS(Vendas!$B$2:$B$3001,$A53,Vendas!$C$2:$C$3001,$B53,Vendas!$AK$2:$AK$3001,"Validado",Vendas!$T$2:$T$3001,"Valor*") | I53: =IF(C53=0,"-",_xlfn.MINIFS(Vendas!$Z$2:$Z$3001,Vendas!$B$2:$B$3001,$A53,Vendas!$C$2:$C$3001,$B53,Vendas!$AK$2:$AK$3001,"Validado")) | J53: =IF(C53=0,"-",_xlfn.MAXIFS(Vendas!$Z$2:$Z$3001,Vendas!$B$2:$B$3001,$A53,Vendas!$C$2:$C$3001,$B53,Vendas!$AK$2:$AK$3001,"Validado"))
A54: Bertioga | B54: Indaiá | C54: =COUNTIFS(Vendas!$B$2:$B$3001,$A54,Vendas!$C$2:$C$3001,$B54,Vendas!$AK$2:$AK$3001,"Validado") | D54: {=IF(C54=0,"-",MEDIAN(IF((Vendas!$B$2:$B$3001=$A54)*(Vendas!$C$2:$C$3001=$B54)*(Vendas!$AK$2:$AK$3001="Validado")*ISNUMBER(Vendas!$M$2:$M$3001),Vendas!$M$2:$M$3001)))} | E54: =IF(C54=0,"-",_xlfn.MINIFS(Vendas!$M$2:$M$3001,Vendas!$B$2:$B$3001,$A54,Vendas!$C$2:$C$3001,$B54,Vendas!$AK$2:$AK$3001,"Validado")) | F54: =IF(C54=0,"-",_xlfn.MAXIFS(Vendas!$M$2:$M$3001,Vendas!$B$2:$B$3001,$A54,Vendas!$C$2:$C$3001,$B54,Vendas!$AK$2:$AK$3001,"Validado")) | G54: {=IF(SUMPRODUCT((Vendas!$B$2:$B$3001=$A54)*(Vendas!$C$2:$C$3001=$B54)*(Vendas!$AK$2:$AK$3001="Validado")*ISNUMBER(Vendas!$S$2:$S$3001))=0,"-",MEDIAN(IF((Vendas!$B$2:$B$3001=$A54)*(Vendas!$C$2:$C$3001=$B54)*(Vendas!$AK$2:$AK$3001="Validado")*ISNUMBER(Vendas!$S$2:$S$3001),Vendas!$S$2:$S$3001)))} | H54: =COUNTIFS(Vendas!$B$2:$B$3001,$A54,Vendas!$C$2:$C$3001,$B54,Vendas!$AK$2:$AK$3001,"Validado",Vendas!$T$2:$T$3001,"Valor*") | I54: =IF(C54=0,"-",_xlfn.MINIFS(Vendas!$Z$2:$Z$3001,Vendas!$B$2:$B$3001,$A54,Vendas!$C$2:$C$3001,$B54,Vendas!$AK$2:$AK$3001,"Validado")) | J54: =IF(C54=0,"-",_xlfn.MAXIFS(Vendas!$Z$2:$Z$3001,Vendas!$B$2:$B$3001,$A54,Vendas!$C$2:$C$3001,$B54,Vendas!$AK$2:$AK$3001,"Validado"))
... A61: Bertioga | B61: T.I. (Terras Indígenas do Rio Silveiras) | C61: =COUNTIFS(Vendas!$B$2:$B$3001,$A61,Vendas!$C$2:$C$3001,$B61,Vendas!$AK$2:$AK$3001,"Validado") | D61: {=IF(C61=0,"-",MEDIAN(IF((Vendas!$B$2:$B$3001=$A61)*(Vendas!$C$2:$C$3001=$B61)*(Vendas!$AK$2:$AK$3001="Validado")*ISNUMBER(Vendas!$M$2:$M$3001),Vendas!$M$2:$M$3001)))} | E61: =IF(C61=0,"-",_xlfn.MINIFS(Vendas!$M$2:$M$3001,Vendas!$B$2:$B$3001,$A61,Vendas!$C$2:$C$3001,$B61,Vendas!$AK$2:$AK$3001,"Validado")) | F61: =IF(C61=0,"-",_xlfn.MAXIFS(Vendas!$M$2:$M$3001,Vendas!$B$2:$B$3001,$A61,Vendas!$C$2:$C$3001,$B61,Vendas!$AK$2:$AK$3001,"Validado")) | G61: {=IF(SUMPRODUCT((Vendas!$B$2:$B$3001=$A61)*(Vendas!$C$2:$C$3001=$B61)*(Vendas!$AK$2:$AK$3001="Validado")*ISNUMBER(Vendas!$S$2:$S$3001))=0,"-",MEDIAN(IF((Vendas!$B$2:$B$3001=$A61)*(Vendas!$C$2:$C$3001=$B61)*(Vendas!$AK$2:$AK$3001="Validado")*ISNUMBER(Vendas!$S$2:$S$3001),Vendas!$S$2:$S$3001)))} | H61: =COUNTIFS(Vendas!$B$2:$B$3001,$A61,Vendas!$C$2:$C$3001,$B61,Vendas!$AK$2:$AK$3001,"Validado",Vendas!$T$2:$T$3001,"Valor*") | I61: =IF(C61=0,"-",_xlfn.MINIFS(Vendas!$Z$2:$Z$3001,Vendas!$B$2:$B$3001,$A61,Vendas!$C$2:$C$3001,$B61,Vendas!$AK$2:$AK$3001,"Validado")) | J61: =IF(C61=0,"-",_xlfn.MAXIFS(Vendas!$Z$2:$Z$3001,Vendas!$B$2:$B$3001,$A61,Vendas!$C$2:$C$3001,$B61,Vendas!$AK$2:$AK$3001,"Validado"))
A62: Bertioga | B62: TOTAL DA CIDADE | C62: =COUNTIFS(Vendas!$B$2:$B$3001,$A62,Vendas!$AK$2:$AK$3001,"Validado") | D62: {=IF(C62=0,"-",MEDIAN(IF((Vendas!$B$2:$B$3001=$A62)*(Vendas!$AK$2:$AK$3001="Validado")*ISNUMBER(Vendas!$M$2:$M$3001),Vendas!$M$2:$M$3001)))} | E62: =IF(C62=0,"-",_xlfn.MINIFS(Vendas!$M$2:$M$3001,Vendas!$B$2:$B$3001,$A62,Vendas!$AK$2:$AK$3001,"Validado")) | F62: =IF(C62=0,"-",_xlfn.MAXIFS(Vendas!$M$2:$M$3001,Vendas!$B$2:$B$3001,$A62,Vendas!$AK$2:$AK$3001,"Validado")) | G62: {=IF(SUMPRODUCT((Vendas!$B$2:$B$3001=$A62)*(Vendas!$AK$2:$AK$3001="Validado")*ISNUMBER(Vendas!$S$2:$S$3001))=0,"-",MEDIAN(IF((Vendas!$B$2:$B$3001=$A62)*(Vendas!$AK$2:$AK$3001="Validado")*ISNUMBER(Vendas!$S$2:$S$3001),Vendas!$S$2:$S$3001)))} | H62: =COUNTIFS(Vendas!$B$2:$B$3001,$A62,Vendas!$AK$2:$AK$3001,"Validado",Vendas!$T$2:$T$3001,"Valor*") | I62: =IF(C62=0,"-",_xlfn.MINIFS(Vendas!$Z$2:$Z$3001,Vendas!$B$2:$B$3001,$A62,Vendas!$AK$2:$AK$3001,"Validado")) | J62: =IF(C62=0,"-",_xlfn.MAXIFS(Vendas!$Z$2:$Z$3001,Vendas!$B$2:$B$3001,$A62,Vendas!$AK$2:$AK$3001,"Validado"))
A65: Resumo por cidade e padrão
A66: Cidade | B66: Padrão | C66: Nº de vendas | D66: Valor mediano (R$) | E66: Menor valor (R$) | F66: Maior valor (R$) | G66: R$/m² mediano
A67: São Sebastião | B67: Baixo | C67: =COUNTIFS(Vendas!$B$2:$B$3001,$A67,Vendas!$J$2:$J$3001,$B67,Vendas!$AK$2:$AK$3001,"Validado") | D67: {=IF(C67=0,"-",MEDIAN(IF((Vendas!$B$2:$B$3001=$A67)*(Vendas!$J$2:$J$3001=$B67)*(Vendas!$AK$2:$AK$3001="Validado")*ISNUMBER(Vendas!$M$2:$M$3001),Vendas!$M$2:$M$3001)))} | E67: =IF(C67=0,"-",_xlfn.MINIFS(Vendas!$M$2:$M$3001,Vendas!$B$2:$B$3001,$A67,Vendas!$J$2:$J$3001,$B67,Vendas!$AK$2:$AK$3001,"Validado")) | F67: =IF(C67=0,"-",_xlfn.MAXIFS(Vendas!$M$2:$M$3001,Vendas!$B$2:$B$3001,$A67,Vendas!$J$2:$J$3001,$B67,Vendas!$AK$2:$AK$3001,"Validado")) | G67: {=IF(SUMPRODUCT((Vendas!$B$2:$B$3001=$A67)*(Vendas!$J$2:$J$3001=$B67)*(Vendas!$AK$2:$AK$3001="Validado")*ISNUMBER(Vendas!$S$2:$S$3001))=0,"-",MEDIAN(IF((Vendas!$B$2:$B$3001=$A67)*(Vendas!$J$2:$J$3001=$B67)*(Vendas!$AK$2:$AK$3001="Validado")*ISNUMBER(Vendas!$S$2:$S$3001),Vendas!$S$2:$S$3001)))}
A68: São Sebastião | B68: Normal | C68: =COUNTIFS(Vendas!$B$2:$B$3001,$A68,Vendas!$J$2:$J$3001,$B68,Vendas!$AK$2:$AK$3001,"Validado") | D68: {=IF(C68=0,"-",MEDIAN(IF((Vendas!$B$2:$B$3001=$A68)*(Vendas!$J$2:$J$3001=$B68)*(Vendas!$AK$2:$AK$3001="Validado")*ISNUMBER(Vendas!$M$2:$M$3001),Vendas!$M$2:$M$3001)))} | E68: =IF(C68=0,"-",_xlfn.MINIFS(Vendas!$M$2:$M$3001,Vendas!$B$2:$B$3001,$A68,Vendas!$J$2:$J$3001,$B68,Vendas!$AK$2:$AK$3001,"Validado")) | F68: =IF(C68=0,"-",_xlfn.MAXIFS(Vendas!$M$2:$M$3001,Vendas!$B$2:$B$3001,$A68,Vendas!$J$2:$J$3001,$B68,Vendas!$AK$2:$AK$3001,"Validado")) | G68: {=IF(SUMPRODUCT((Vendas!$B$2:$B$3001=$A68)*(Vendas!$J$2:$J$3001=$B68)*(Vendas!$AK$2:$AK$3001="Validado")*ISNUMBER(Vendas!$S$2:$S$3001))=0,"-",MEDIAN(IF((Vendas!$B$2:$B$3001=$A68)*(Vendas!$J$2:$J$3001=$B68)*(Vendas!$AK$2:$AK$3001="Validado")*ISNUMBER(Vendas!$S$2:$S$3001),Vendas!$S$2:$S$3001)))}
A69: São Sebastião | B69: Alto | C69: =COUNTIFS(Vendas!$B$2:$B$3001,$A69,Vendas!$J$2:$J$3001,$B69,Vendas!$AK$2:$AK$3001,"Validado") | D69: {=IF(C69=0,"-",MEDIAN(IF((Vendas!$B$2:$B$3001=$A69)*(Vendas!$J$2:$J$3001=$B69)*(Vendas!$AK$2:$AK$3001="Validado")*ISNUMBER(Vendas!$M$2:$M$3001),Vendas!$M$2:$M$3001)))} | E69: =IF(C69=0,"-",_xlfn.MINIFS(Vendas!$M$2:$M$3001,Vendas!$B$2:$B$3001,$A69,Vendas!$J$2:$J$3001,$B69,Vendas!$AK$2:$AK$3001,"Validado")) | F69: =IF(C69=0,"-",_xlfn.MAXIFS(Vendas!$M$2:$M$3001,Vendas!$B$2:$B$3001,$A69,Vendas!$J$2:$J$3001,$B69,Vendas!$AK$2:$AK$3001,"Validado")) | G69: {=IF(SUMPRODUCT((Vendas!$B$2:$B$3001=$A69)*(Vendas!$J$2:$J$3001=$B69)*(Vendas!$AK$2:$AK$3001="Validado")*ISNUMBER(Vendas!$S$2:$S$3001))=0,"-",MEDIAN(IF((Vendas!$B$2:$B$3001=$A69)*(Vendas!$J$2:$J$3001=$B69)*(Vendas!$AK$2:$AK$3001="Validado")*ISNUMBER(Vendas!$S$2:$S$3001),Vendas!$S$2:$S$3001)))}
A70: São Sebastião | B70: Não informado | C70: =COUNTIFS(Vendas!$B$2:$B$3001,$A70,Vendas!$J$2:$J$3001,$B70,Vendas!$AK$2:$AK$3001,"Validado") | D70: {=IF(C70=0,"-",MEDIAN(IF((Vendas!$B$2:$B$3001=$A70)*(Vendas!$J$2:$J$3001=$B70)*(Vendas!$AK$2:$AK$3001="Validado")*ISNUMBER(Vendas!$M$2:$M$3001),Vendas!$M$2:$M$3001)))} | E70: =IF(C70=0,"-",_xlfn.MINIFS(Vendas!$M$2:$M$3001,Vendas!$B$2:$B$3001,$A70,Vendas!$J$2:$J$3001,$B70,Vendas!$AK$2:$AK$3001,"Validado")) | F70: =IF(C70=0,"-",_xlfn.MAXIFS(Vendas!$M$2:$M$3001,Vendas!$B$2:$B$3001,$A70,Vendas!$J$2:$J$3001,$B70,Vendas!$AK$2:$AK$3001,"Validado")) | G70: {=IF(SUMPRODUCT((Vendas!$B$2:$B$3001=$A70)*(Vendas!$J$2:$J$3001=$B70)*(Vendas!$AK$2:$AK$3001="Validado")*ISNUMBER(Vendas!$S$2:$S$3001))=0,"-",MEDIAN(IF((Vendas!$B$2:$B$3001=$A70)*(Vendas!$J$2:$J$3001=$B70)*(Vendas!$AK$2:$AK$3001="Validado")*ISNUMBER(Vendas!$S$2:$S$3001),Vendas!$S$2:$S$3001)))}
A71: Bertioga | B71: Baixo | C71: =COUNTIFS(Vendas!$B$2:$B$3001,$A71,Vendas!$J$2:$J$3001,$B71,Vendas!$AK$2:$AK$3001,"Validado") | D71: {=IF(C71=0,"-",MEDIAN(IF((Vendas!$B$2:$B$3001=$A71)*(Vendas!$J$2:$J$3001=$B71)*(Vendas!$AK$2:$AK$3001="Validado")*ISNUMBER(Vendas!$M$2:$M$3001),Vendas!$M$2:$M$3001)))} | E71: =IF(C71=0,"-",_xlfn.MINIFS(Vendas!$M$2:$M$3001,Vendas!$B$2:$B$3001,$A71,Vendas!$J$2:$J$3001,$B71,Vendas!$AK$2:$AK$3001,"Validado")) | F71: =IF(C71=0,"-",_xlfn.MAXIFS(Vendas!$M$2:$M$3001,Vendas!$B$2:$B$3001,$A71,Vendas!$J$2:$J$3001,$B71,Vendas!$AK$2:$AK$3001,"Validado")) | G71: {=IF(SUMPRODUCT((Vendas!$B$2:$B$3001=$A71)*(Vendas!$J$2:$J$3001=$B71)*(Vendas!$AK$2:$AK$3001="Validado")*ISNUMBER(Vendas!$S$2:$S$3001))=0,"-",MEDIAN(IF((Vendas!$B$2:$B$3001=$A71)*(Vendas!$J$2:$J$3001=$B71)*(Vendas!$AK$2:$AK$3001="Validado")*ISNUMBER(Vendas!$S$2:$S$3001),Vendas!$S$2:$S$3001)))}
A72: Bertioga | B72: Normal | C72: =COUNTIFS(Vendas!$B$2:$B$3001,$A72,Vendas!$J$2:$J$3001,$B72,Vendas!$AK$2:$AK$3001,"Validado") | D72: {=IF(C72=0,"-",MEDIAN(IF((Vendas!$B$2:$B$3001=$A72)*(Vendas!$J$2:$J$3001=$B72)*(Vendas!$AK$2:$AK$3001="Validado")*ISNUMBER(Vendas!$M$2:$M$3001),Vendas!$M$2:$M$3001)))} | E72: =IF(C72=0,"-",_xlfn.MINIFS(Vendas!$M$2:$M$3001,Vendas!$B$2:$B$3001,$A72,Vendas!$J$2:$J$3001,$B72,Vendas!$AK$2:$AK$3001,"Validado")) | F72: =IF(C72=0,"-",_xlfn.MAXIFS(Vendas!$M$2:$M$3001,Vendas!$B$2:$B$3001,$A72,Vendas!$J$2:$J$3001,$B72,Vendas!$AK$2:$AK$3001,"Validado")) | G72: {=IF(SUMPRODUCT((Vendas!$B$2:$B$3001=$A72)*(Vendas!$J$2:$J$3001=$B72)*(Vendas!$AK$2:$AK$3001="Validado")*ISNUMBER(Vendas!$S$2:$S$3001))=0,"-",MEDIAN(IF((Vendas!$B$2:$B$3001=$A72)*(Vendas!$J$2:$J$3001=$B72)*(Vendas!$AK$2:$AK$3001="Validado")*ISNUMBER(Vendas!$S$2:$S$3001),Vendas!$S$2:$S$3001)))}
A73: Bertioga | B73: Alto | C73: =COUNTIFS(Vendas!$B$2:$B$3001,$A73,Vendas!$J$2:$J$3001,$B73,Vendas!$AK$2:$AK$3001,"Validado") | D73: {=IF(C73=0,"-",MEDIAN(IF((Vendas!$B$2:$B$3001=$A73)*(Vendas!$J$2:$J$3001=$B73)*(Vendas!$AK$2:$AK$3001="Validado")*ISNUMBER(Vendas!$M$2:$M$3001),Vendas!$M$2:$M$3001)))} | E73: =IF(C73=0,"-",_xlfn.MINIFS(Vendas!$M$2:$M$3001,Vendas!$B$2:$B$3001,$A73,Vendas!$J$2:$J$3001,$B73,Vendas!$AK$2:$AK$3001,"Validado")) | F73: =IF(C73=0,"-",_xlfn.MAXIFS(Vendas!$M$2:$M$3001,Vendas!$B$2:$B$3001,$A73,Vendas!$J$2:$J$3001,$B73,Vendas!$AK$2:$AK$3001,"Validado")) | G73: {=IF(SUMPRODUCT((Vendas!$B$2:$B$3001=$A73)*(Vendas!$J$2:$J$3001=$B73)*(Vendas!$AK$2:$AK$3001="Validado")*ISNUMBER(Vendas!$S$2:$S$3001))=0,"-",MEDIAN(IF((Vendas!$B$2:$B$3001=$A73)*(Vendas!$J$2:$J$3001=$B73)*(Vendas!$AK$2:$AK$3001="Validado")*ISNUMBER(Vendas!$S$2:$S$3001),Vendas!$S$2:$S$3001)))}
...

Sheet Análise ITBI
A1: Análise de subdeclaração do valor de venda no ITBI
A2: Usa só vendas com Status = Validado. Nenhum número é estimado: cada indicador sai dos documentos lançados na aba Vendas. Recortes com menos vendas que a amostra mínima mostram 'n<mín'.
A4: Amostra mínima (n) | B4: 5
A5: Método e leitura: ver docs/analise_subdeclaracao_ITBI.md. Passe o mouse nos cabeçalhos para a definição de cada indicador.
A7: Por cidade
A8: Cidade | B8: Recorte | C8: Nº vendas validadas | D8: Nº c/ base ITBI | E8: Mediana Declarado ÷ Base ITBI | F8: % c/ base > declarado | G8: COD Declarado ÷ Base | H8: Nº c/ venal IPTU | I8: Mediana Declarado ÷ Venal | J8: % declarado ≤ venal | K8: Nº financiadas (c/ m²) | L8: Nº à vista (c/ m²) | M8: R$/m² mediano financiadas | N8: R$/m² mediano à vista | O8: Dif. à vista vs financiada | P8: Nº c/ valor leilão | Q8: Mediana Declarado ÷ Leilão | R8: % declarado < leilão | S8: Nº c/ valor financiado | T8: % financiado ≥ declarado
